Workbook

Sheet Dashboard
B2: 📊 DASHBOARD EMPRESARIAL | K2: PLANTILLA INTEGRAL DE GESTIÓN PyME
B3: Indicadores actualizados automáticamente · Ingresa tus datos en cada módulo
B6: 💰 VENTAS DEL MES | G6: 🛒 COMPRAS DEL MES | L6: 📥 CTAS. POR COBRAR | Q6: 🏦 SALDO CAJA
B7: =Ventas!M3 | G7: =Compras!L3 | L7: =Ctas_Cobrar!L3 | Q7: =Caja!Q6
B9: Total facturas emitidas | G9: Total órdenes de compra | L9: Pendiente de cobro | Q9: Saldo disponible hoy
B15: 📤 CTAS. POR PAGAR | G15: 📈 RESULTADO CONTABLE | L15: 📦 STOCK VALORIZADO | Q15: 🎯 MARGEN ESTIMADO
B16: =Ctas_Pagar!K3 | G16: =Contabilidad!L3 | L16: =Inventario!M3 | Q16: =IFERROR((Ventas!M3-Compras!L3)/Ventas!M3,0)
B18: Compromisos pendientes | G18: Resultado del período | L18: Valor total inventario | Q18: Margen bruto del mes
B23: 📅 RESUMEN MENSUAL
B24: CONCEPTO | C24: Ene | D24: Feb | E24: Mar | F24: Abr | G24: May | H24: Jun | I24: Jul | J24: Ago | K24: Sep | L24: Oct | M24: Nov | N24: Dic | O24: TOTAL
B25: Ventas | C25: =SUMIFS(Ventas!H:H,Ventas!J:J,1,Ventas!K:K,YEAR(TODAY())) | D25: =SUMIFS(Ventas!H:H,Ventas!J:J,2,Ventas!K:K,YEAR(TODAY())) | E25: =SUMIFS(Ventas!H:H,Ventas!J:J,3,Ventas!K:K,YEAR(TODAY())) | F25: =SUMIFS(Ventas!H:H,Ventas!J:J,4,Ventas!K:K,YEAR(TODAY())) | G25: =SUMIFS(Ventas!H:H,Ventas!J:J,5,Ventas!K:K,YEAR(TODAY())) | H25: =SUMIFS(Ventas!H:H,Ventas!J:J,6,Ventas!K:K,YEAR(TODAY())) | I25: =SUMIFS(Ventas!H:H,Ventas!J:J,7,Ventas!K:K,YEAR(TODAY())) | J25: =SUMIFS(Ventas!H:H,Ventas!J:J,8,Ventas!K:K,YEAR(TODAY())) | K25: =SUMIFS(Ventas!H:H,Ventas!J:J,9,Ventas!K:K,YEAR(TODAY())) | L25: =SUMIFS(Ventas!H:H,Ventas!J:J,10,Ventas!K:K,YEAR(TODAY())) | M25: =SUMIFS(Ventas!H:H,Ventas!J:J,11,Ventas!K:K,YEAR(TODAY())) | N25: =SUMIFS(Ventas!H:H,Ventas!J:J,12,Ventas!K:K,YEAR(TODAY())) | O25: =SUM(C25:N25)
B26: Compras | C26: =SUMIFS(Compras!H:H,Compras!I:I,1,Compras!J:J,YEAR(TODAY())) | D26: =SUMIFS(Compras!H:H,Compras!I:I,2,Compras!J:J,YEAR(TODAY())) | E26: =SUMIFS(Compras!H:H,Compras!I:I,3,Compras!J:J,YEAR(TODAY())) | F26: =SUMIFS(Compras!H:H,Compras!I:I,4,Compras!J:J,YEAR(TODAY())) | G26: =SUMIFS(Compras!H:H,Compras!I:I,5,Compras!J:J,YEAR(TODAY())) | H26: =SUMIFS(Compras!H:H,Compras!I:I,6,Compras!J:J,YEAR(TODAY())) | I26: =SUMIFS(Compras!H:H,Compras!I:I,7,Compras!J:J,YEAR(TODAY())) | J26: =SUMIFS(Compras!H:H,Compras!I:I,8,Compras!J:J,YEAR(TODAY())) | K26: =SUMIFS(Compras!H:H,Compras!I:I,9,Compras!J:J,YEAR(TODAY())) | L26: =SUMIFS(Compras!H:H,Compras!I:I,10,Compras!J:J,YEAR(TODAY())) | M26: =SUMIFS(Compras!H:H,Compras!I:I,11,Compras!J:J,YEAR(TODAY())) | N26: =SUMIFS(Compras!H:H,Compras!I:I,12,Compras!J:J,YEAR(TODAY())) | O26: =SUM(C26:N26)
B27: Resultado | C27: =SUMIFS(Contabilidad!F:F,Contabilidad!H:H,1)-SUMIFS(Contabilidad!G:G,Contabilidad!H:H,1) | D27: =SUMIFS(Contabilidad!F:F,Contabilidad!H:H,2)-SUMIFS(Contabilidad!G:G,Contabilidad!H:H,2) | E27: =SUMIFS(Contabilidad!F:F,Contabilidad!H:H,3)-SUMIFS(Contabilidad!G:G,Contabilidad!H:H,3) | F27: =SUMIFS(Contabilidad!F:F,Contabilidad!H:H,4)-SUMIFS(Contabilidad!G:G,Contabilidad!H:H,4) | G27: =SUMIFS(Contabilidad!F:F,Contabilidad!H:H,5)-SUMIFS(Contabilidad!G:G,Contabilidad!H:H,5) | H27: =SUMIFS(Contabilidad!F:F,Contabilidad!H:H,6)-SUMIFS(Contabilidad!G:G,Contabilidad!H:H,6) | I27: =SUMIFS(Contabilidad!F:F,Contabilidad!H:H,7)-SUMIFS(Contabilidad!G:G,Contabilidad!H:H,7) | J27: =SUMIFS(Contabilidad!F:F,Contabilidad!H:H,8)-SUMIFS(Contabilidad!G:G,Contabilidad!H:H,8) | K27: =SUMIFS(Contabilidad!F:F,Contabilidad!H:H,9)-SUMIFS(Contabilidad!G:G,Contabilidad!H:H,9) | L27: =SUMIFS(Contabilidad!F:F,Contabilidad!H:H,10)-SUMIFS(Contabilidad!G:G,Contabilidad!H:H,10) | M27: =SUMIFS(Contabilidad!F:F,Contabilidad!H:H,11)-SUMIFS(Contabilidad!G:G,Contabilidad!H:H,11) | N27: =SUMIFS(Contabilidad!F:F,Contabilidad!H:H,12)-SUMIFS(Contabilidad!G:G,Contabilidad!H:H,12) | O27: =SUM(C27:N27)
B29: ⚠️ ALERTAS Y SEMÁFOROS
B30: Conciliación bancaria | G30: Ctas. por cobrar vencidas | L30: Ctas. por pagar vencidas | Q30: Productos bajo stock mínimo
B31: =IF(Conciliacion!K8=0,"✅ CUADRADA","❌ DESCUADRE: "&TEXT(ABS(Conciliacion!K8),"#,##0")) | G31: =COUNTIFS(Ctas_Cobrar!H:H,"Vencido")&" documento(s) vencido(s)" | L31: =COUNTIFS(Ctas_Pagar!H:H,"Vencido")&" pago(s) vencido(s)" | Q31: =Inventario!N3&" producto(s) bajo mínimo"
A100: Mes | B100: Ventas | C100: Compras | D100: Resultado
A101: Ene | B101: =SUMIFS(Ventas!H:H,Ventas!J:J,1,Ventas!K:K,YEAR(TODAY())) | C101: =SUMIFS(Compras!H:H,Compras!I:I,1,Compras!J:J,YEAR(TODAY())) | D101: =B101-C101
A102: Feb | B102: =SUMIFS(Ventas!H:H,Ventas!J:J,2,Ventas!K:K,YEAR(TODAY())) | C102: =SUMIFS(Compras!H:H,Compras!I:I,2,Compras!J:J,YEAR(TODAY())) | D102: =B102-C102
A103: Mar | B103: =SUMIFS(Ventas!H:H,Ventas!J:J,3,Ventas!K:K,YEAR(TODAY())) | C103: =SUMIFS(Compras!H:H,Compras!I:I,3,Compras!J:J,YEAR(TODAY())) | D103: =B103-C103
A104: Abr | B104: =SUMIFS(Ventas!H:H,Ventas!J:J,4,Ventas!K:K,YEAR(TODAY())) | C104: =SUMIFS(Compras!H:H,Compras!I:I,4,Compras!J:J,YEAR(TODAY())) | D104: =B104-C104
A105: May | B105: =SUMIFS(Ventas!H:H,Ventas!J:J,5,Ventas!K:K,YEAR(TODAY())) | C105: =SUMIFS(Compras!H:H,Compras!I:I,5,Compras!J:J,YEAR(TODAY())) | D105: =B105-C105
A106: Jun | B106: =SUMIFS(Ventas!H:H,Ventas!J:J,6,Ventas!K:K,YEAR(TODAY())) | C106: =SUMIFS(Compras!H:H,Compras!I:I,6,Compras!J:J,YEAR(TODAY())) | D106: =B106-C106
A107: Jul | B107: =SUMIFS(Ventas!H:H,Ventas!J:J,7,Ventas!K:K,YEAR(TODAY())) | C107: =SUMIFS(Compras!H:H,Compras!I:I,7,Compras!J:J,YEAR(TODAY())) | D107: =B107-C107
A108: Ago | B108: =SUMIFS(Ventas!H:H,Ventas!J:J,8,Ventas!K:K,YEAR(TODAY())) | C108: =SUMIFS(Compras!H:H,Compras!I:I,8,Compras!J:J,YEAR(TODAY())) | D108: =B108-C108
A109: Sep | B109: =SUMIFS(Ventas!H:H,Ventas!J:J,9,Ventas!K:K,YEAR(TODAY())) | C109: =SUMIFS(Compras!H:H,Compras!I:I,9,Compras!J:J,YEAR(TODAY())) | D109: =B109-C109
A110: Oct | B110: =SUMIFS(Ventas!H:H,Ventas!J:J,10,Ventas!K:K,YEAR(TODAY())) | C110: =SUMIFS(Compras!H:H,Compras!I:I,10,Compras!J:J,YEAR(TODAY())) | D110: =B110-C110
A111: Nov | B111: =SUMIFS(Ventas!H:H,Ventas!J:J,11,Ventas!K:K,YEAR(TODAY())) | C111: =SUMIFS(Compras!H:H,Compras!I:I,11,Compras!J:J,YEAR(TODAY())) | D111: =B111-C111
A112: Dic | B112: =SUMIFS(Ventas!H:H,Ventas!J:J,12,Ventas!K:K,YEAR(TODAY())) | C112: =SUMIFS(Compras!H:H,Compras!I:I,12,Compras!J:J,YEAR(TODAY())) | D112: =B112-C112

Sheet Resumen_Ejecutivo
B2: RESUMEN EJECUTIVO | J2: =TEXT(TODAY(),"Período a DD de MMMM de YYYY")
B5: 💰 VENTAS DEL MES | F5: 🛒 COMPRAS DEL MES | J5: 📈 RESULTADO NETO | N5: 🎯 MARGEN BRUTO
B6: =Ventas!M3 | F6: =Compras!L3 | J6: =Contabilidad!L3 | N6: =IFERROR((Ventas!M3-Compras!L3)/Ventas!M3,0)
B9: 🏦 SALDO CAJA | F9: 📥 CTAS POR COBRAR | J9: 📤 CTAS POR PAGAR | N9: 📦 STOCK VALORIZADO
B10: =Caja!Q6 | F10: =Ctas_Cobrar!L3 | J10: =Ctas_Pagar!K3 | N10: =Inventario!M3
B13: EVOLUCIÓN MENSUAL
B14: CONCEPTO | C14: E | D14: F | E14: M | F14: A | G14: M | H14: J | I14: J | J14: A | K14: S | L14: O | M14: N | N14: D | O14: TOTAL
B15: Ventas | C15: =SUMIFS(Ventas!H:H,Ventas!J:J,1,Ventas!K:K,YEAR(TODAY())) | D15: =SUMIFS(Ventas!H:H,Ventas!J:J,2,Ventas!K:K,YEAR(TODAY())) | E15: =SUMIFS(Ventas!H:H,Ventas!J:J,3,Ventas!K:K,YEAR(TODAY())) | F15: =SUMIFS(Ventas!H:H,Ventas!J:J,4,Ventas!K:K,YEAR(TODAY())) | G15: =SUMIFS(Ventas!H:H,Ventas!J:J,5,Ventas!K:K,YEAR(TODAY())) | H15: =SUMIFS(Ventas!H:H,Ventas!J:J,6,Ventas!K:K,YEAR(TODAY())) | I15: =SUMIFS(Ventas!H:H,Ventas!J:J,7,Ventas!K:K,YEAR(TODAY())) | J15: =SUMIFS(Ventas!H:H,Ventas!J:J,8,Ventas!K:K,YEAR(TODAY())) | K15: =SUMIFS(Ventas!H:H,Ventas!J:J,9,Ventas!K:K,YEAR(TODAY())) | L15: =SUMIFS(Ventas!H:H,Ventas!J:J,10,Ventas!K:K,YEAR(TODAY())) | M15: =SUMIFS(Ventas!H:H,Ventas!J:J,11,Ventas!K:K,YEAR(TODAY())) | N15: =SUMIFS(Ventas!H:H,Ventas!J:J,12,Ventas!K:K,YEAR(TODAY())) | O15: =SUM(C15:N15)
B16: Compras | C16: =SUMIFS(Compras!H:H,Compras!I:I,1,Compras!J:J,YEAR(TODAY())) | D16: =SUMIFS(Compras!H:H,Compras!I:I,2,Compras!J:J,YEAR(TODAY())) | E16: =SUMIFS(Compras!H:H,Compras!I:I,3,Compras!J:J,YEAR(TODAY())) | F16: =SUMIFS(Compras!H:H,Compras!I:I,4,Compras!J:J,YEAR(TODAY())) | G16: =SUMIFS(Compras!H:H,Compras!I:I,5,Compras!J:J,YEAR(TODAY())) | H16: =SUMIFS(Compras!H:H,Compras!I:I,6,Compras!J:J,YEAR(TODAY())) | I16: =SUMIFS(Compras!H:H,Compras!I:I,7,Compras!J:J,YEAR(TODAY())) | J16: =SUMIFS(Compras!H:H,Compras!I:I,8,Compras!J:J,YEAR(TODAY())) | K16: =SUMIFS(Compras!H:H,Compras!I:I,9,Compras!J:J,YEAR(TODAY())) | L16: =SUMIFS(Compras!H:H,Compras!I:I,10,Compras!J:J,YEAR(TODAY())) | M16: =SUMIFS(Compras!H:H,Compras!I:I,11,Compras!J:J,YEAR(TODAY())) | N16: =SUMIFS(Compras!H:H,Compras!I:I,12,Compras!J:J,YEAR(TODAY())) | O16: =SUM(C16:N16)
B17: Resultado | C17: =SUMIFS(Contabilidad!F:F,Contabilidad!H:H,1)-SUMIFS(Contabilidad!G:G,Contabilidad!H:H,1) | D17: =SUMIFS(Contabilidad!F:F,Contabilidad!H:H,2)-SUMIFS(Contabilidad!G:G,Contabilidad!H:H,2) | E17: =SUMIFS(Contabilidad!F:F,Contabilidad!H:H,3)-SUMIFS(Contabilidad!G:G,Contabilidad!H:H,3) | F17: =SUMIFS(Contabilidad!F:F,Contabilidad!H:H,4)-SUMIFS(Contabilidad!G:G,Contabilidad!H:H,4) | G17: =SUMIFS(Contabilidad!F:F,Contabilidad!H:H,5)-SUMIFS(Contabilidad!G:G,Contabilidad!H:H,5) | H17: =SUMIFS(Contabilidad!F:F,Contabilidad!H:H,6)-SUMIFS(Contabilidad!G:G,Contabilidad!H:H,6) | I17: =SUMIFS(Contabilidad!F:F,Contabilidad!H:H,7)-SUMIFS(Contabilidad!G:G,Contabilidad!H:H,7) | J17: =SUMIFS(Contabilidad!F:F,Contabilidad!H:H,8)-SUMIFS(Contabilidad!G:G,Contabilidad!H:H,8) | K17: =SUMIFS(Contabilidad!F:F,Contabilidad!H:H,9)-SUMIFS(Contabilidad!G:G,Contabilidad!H:H,9) | L17: =SUMIFS(Contabilidad!F:F,Contabilidad!H:H,10)-SUMIFS(Contabilidad!G:G,Contabilidad!H:H,10) | M17: =SUMIFS(Contabilidad!F:F,Contabilidad!H:H,11)-SUMIFS(Contabilidad!G:G,Contabilidad!H:H,11) | N17: =SUMIFS(Contabilidad!F:F,Contabilidad!H:H,12)-SUMIFS(Contabilidad!G:G,Contabilidad!H:H,12) | O17: =SUM(C17:N17)
B22: RATIOS CLAVE DEL PERIODO
B24: MARGEN BRUTO | I24: ROTACIÓN CXC (DÍAS)
B25: =IFERROR((Ventas!M3-Compras!L3)/Ventas!M3,0) | I25: =IFERROR(Ctas_Cobrar!L3/(Ventas!M3/30),0)
B26: Cuánto queda de cada peso de venta | I26: Días promedio para cobrar
B28: ROTACIÓN CXP (DÍAS) | I28: COBERTURA DE DEUDA
B29: =IFERROR(Ctas_Pagar!K3/(Compras!L3/30),0) | I29: =IFERROR(Caja!Q6/Ctas_Pagar!K3,0)
B30: Días promedio para pagar | I30: Cuántas veces cubre la caja las CxP
B32: % VENTAS COBRADAS | I32: RESULTADO S/ VENTAS
B33: =IFERROR(1-Ctas_Cobrar!L3/Ventas!M3,0) | I33: =IFERROR(Contabilidad!L3/Ventas!M3,0)
B34: Porcentaje ya cobrado del total vendido | I34: Rentabilidad neta sobre ventas
B38: ANÁLISIS AUTOMÁTICO
B39: =IF(Ventas!M3>Compras!L3,"✅ Ventas superan a Compras en $"&TEXT(Ventas!M3-Compras!L3,"#,##0")&" — resultado positivo del período.","⚠️ Compras superan a Ventas en $"&TEXT(Compras!L3-Ventas!M3,"#,##0")&" — revisar márgenes.")
B40: =IF(Ctas_Cobrar!L3=0,"✅ Sin cuentas por cobrar pendientes — cartera al día.","📥 Cartera pendiente de $"&TEXT(Ctas_Cobrar!L3,"#,##0")&". Gestionar cobros prioritariamente.")
B41: =IF(Ctas_Pagar!K3=0,"✅ Sin obligaciones de pago pendientes.","📤 Compromisos por pagar: $"&TEXT(Ctas_Pagar!K3,"#,##0")&". Verificar disponibilidad en caja.")
B42: =IF(Caja!Q6>Ctas_Pagar!K3,"✅ Caja cubre todas las obligaciones pendientes.","🔴 Caja insuficiente para cubrir las CxP. Déficit de $"&TEXT(ABS(Caja!Q6-Ctas_Pagar!K3),"#,##0")&".")

Sheet Vencimientos
A2: 📅 AGENDA DE VENCIMIENTOS — Próximos 90 días
A5: 📥 COBROS PENDIENTES (desde Cuentas por Cobrar)
A6: N° Doc | B6: Fecha | C6: Cliente | D6: Importe | E6: Cobrado | F6: Saldo | G6: Vencimiento | H6: Estado | I6: Días Atraso | J6: Alerta
A7: =IF(Ctas_Cobrar!A5="","",Ctas_Cobrar!A5) | B7: =IF(Ctas_Cobrar!B5="","",Ctas_Cobrar!B5) | C7: =IF(Ctas_Cobrar!C5="","",Ctas_Cobrar!C5) | D7: =IF(Ctas_Cobrar!D5="","",Ctas_Cobrar!D5) | E7: =IF(Ctas_Cobrar!E5="","",Ctas_Cobrar!E5) | F7: =IF(Ctas_Cobrar!F5="","",Ctas_Cobrar!F5) | G7: =IF(Ctas_Cobrar!G5="","",Ctas_Cobrar!G5) | H7: =IF(Ctas_Cobrar!H5="","",Ctas_Cobrar!H5) | I7: =IF(Ctas_Cobrar!I5="","",Ctas_Cobrar!I5) | J7: =IF(Ctas_Cobrar!L5="","",Ctas_Cobrar!L5)
A8: =IF(Ctas_Cobrar!A6="","",Ctas_Cobrar!A6) | B8: =IF(Ctas_Cobrar!B6="","",Ctas_Cobrar!B6) | C8: =IF(Ctas_Cobrar!C6="","",Ctas_Cobrar!C6) | D8: =IF(Ctas_Cobrar!D6="","",Ctas_Cobrar!D6) | E8: =IF(Ctas_Cobrar!E6="","",Ctas_Cobrar!E6) | F8: =IF(Ctas_Cobrar!F6="","",Ctas_Cobrar!F6) | G8: =IF(Ctas_Cobrar!G6="","",Ctas_Cobrar!G6) | H8: =IF(Ctas_Cobrar!H6="","",Ctas_Cobrar!H6) | I8: =IF(Ctas_Cobrar!I6="","",Ctas_Cobrar!I6) | J8: =IF(Ctas_Cobrar!L6="","",Ctas_Cobrar!L6)
A9: =IF(Ctas_Cobrar!A7="","",Ctas_Cobrar!A7) | B9: =IF(Ctas_Cobrar!B7="","",Ctas_Cobrar!B7) | C9: =IF(Ctas_Cobrar!C7="","",Ctas_Cobrar!C7) | D9: =IF(Ctas_Cobrar!D7="","",Ctas_Cobrar!D7) | E9: =IF(Ctas_Cobrar!E7="","",Ctas_Cobrar!E7) | F9: =IF(Ctas_Cobrar!F7="","",Ctas_Cobrar!F7) | G9: =IF(Ctas_Cobrar!G7="","",Ctas_Cobrar!G7) | H9: =IF(Ctas_Cobrar!H7="","",Ctas_Cobrar!H7) | I9: =IF(Ctas_Cobrar!I7="","",Ctas_Cobrar!I7) | J9: =IF(Ctas_Cobrar!L7="","",Ctas_Cobrar!L7)
A10: =IF(Ctas_Cobrar!A8="","",Ctas_Cobrar!A8) | B10: =IF(Ctas_Cobrar!B8="","",Ctas_Cobrar!B8) | C10: =IF(Ctas_Cobrar!C8="","",Ctas_Cobrar!C8) | D10: =IF(Ctas_Cobrar!D8="","",Ctas_Cobrar!D8) | E10: =IF(Ctas_Cobrar!E8="","",Ctas_Cobrar!E8) | F10: =IF(Ctas_Cobrar!F8="","",Ctas_Cobrar!F8) | G10: =IF(Ctas_Cobrar!G8="","",Ctas_Cobrar!G8) | H10: =IF(Ctas_Cobrar!H8="","",Ctas_Cobrar!H8) | I10: =IF(Ctas_Cobrar!I8="","",Ctas_Cobrar!I8) | J10: =IF(Ctas_Cobrar!L8="","",Ctas_Cobrar!L8)
A11: =IF(Ctas_Cobrar!A9="","",Ctas_Cobrar!A9) | B11: =IF(Ctas_Cobrar!B9="","",Ctas_Cobrar!B9) | C11: =IF(Ctas_Cobrar!C9="","",Ctas_Cobrar!C9) | D11: =IF(Ctas_Cobrar!D9="","",Ctas_Cobrar!D9) | E11: =IF(Ctas_Cobrar!E9="","",Ctas_Cobrar!E9) | F11: =IF(Ctas_Cobrar!F9="","",Ctas_Cobrar!F9) | G11: =IF(Ctas_Cobrar!G9="","",Ctas_Cobrar!G9) | H11: =IF(Ctas_Cobrar!H9="","",Ctas_Cobrar!H9) | I11: =IF(Ctas_Cobrar!I9="","",Ctas_Cobrar!I9) | J11: =IF(Ctas_Cobrar!L9="","",Ctas_Cobrar!L9)
A12: =IF(Ctas_Cobrar!A10="","",Ctas_Cobrar!A10) | B12: =IF(Ctas_Cobrar!B10="","",Ctas_Cobrar!B10) | C12: =IF(Ctas_Cobrar!C10="","",Ctas_Cobrar!C10) | D12: =IF(Ctas_Cobrar!D10="","",Ctas_Cobrar!D10) | E12: =IF(Ctas_Cobrar!E10="","",Ctas_Cobrar!E10) | F12: =IF(Ctas_Cobrar!F10="","",Ctas_Cobrar!F10) | G12: =IF(Ctas_Cobrar!G10="","",Ctas_Cobrar!G10) | H12: =IF(Ctas_Cobrar!H10="","",Ctas_Cobrar!H10) | I12: =IF(Ctas_Cobrar!I10="","",Ctas_Cobrar!I10) | J12: =IF(Ctas_Cobrar!L10="","",Ctas_Cobrar!L10)
A13: =IF(Ctas_Cobrar!A11="","",Ctas_Cobrar!A11) | B13: =IF(Ctas_Cobrar!B11="","",Ctas_Cobrar!B11) | C13: =IF(Ctas_Cobrar!C11="","",Ctas_Cobrar!C11) | D13: =IF(Ctas_Cobrar!D11="","",Ctas_Cobrar!D11) | E13: =IF(Ctas_Cobrar!E11="","",Ctas_Cobrar!E11) | F13: =IF(Ctas_Cobrar!F11="","",Ctas_Cobrar!F11) | G13: =IF(Ctas_Cobrar!G11="","",Ctas_Cobrar!G11) | H13: =IF(Ctas_Cobrar!H11="","",Ctas_Cobrar!H11) | I13: =IF(Ctas_Cobrar!I11="","",Ctas_Cobrar!I11) | J13: =IF(Ctas_Cobrar!L11="","",Ctas_Cobrar!L11)
A14: =IF(Ctas_Cobrar!A12="","",Ctas_Cobrar!A12) | B14: =IF(Ctas_Cobrar!B12="","",Ctas_Cobrar!B12) | C14: =IF(Ctas_Cobrar!C12="","",Ctas_Cobrar!C12) | D14: =IF(Ctas_Cobrar!D12="","",Ctas_Cobrar!D12) | E14: =IF(Ctas_Cobrar!E12="","",Ctas_Cobrar!E12) | F14: =IF(Ctas_Cobrar!F12="","",Ctas_Cobrar!F12) | G14: =IF(Ctas_Cobrar!G12="","",Ctas_Cobrar!G12) | H14: =IF(Ctas_Cobrar!H12="","",Ctas_Cobrar!H12) | I14: =IF(Ctas_Cobrar!I12="","",Ctas_Cobrar!I12) | J14: =IF(Ctas_Cobrar!L12="","",Ctas_Cobrar!L12)
A15: =IF(Ctas_Cobrar!A13="","",Ctas_Cobrar!A13) | B15: =IF(Ctas_Cobrar!B13="","",Ctas_Cobrar!B13) | C15: =IF(Ctas_Cobrar!C13="","",Ctas_Cobrar!C13) | D15: =IF(Ctas_Cobrar!D13="","",Ctas_Cobrar!D13) | E15: =IF(Ctas_Cobrar!E13="","",Ctas_Cobrar!E13) | F15: =IF(Ctas_Cobrar!F13="","",Ctas_Cobrar!F13) | G15: =IF(Ctas_Cobrar!G13="","",Ctas_Cobrar!G13) | H15: =IF(Ctas_Cobrar!H13="","",Ctas_Cobrar!H13) | I15: =IF(Ctas_Cobrar!I13="","",Ctas_Cobrar!I13) | J15: =IF(Ctas_Cobrar!L13="","",Ctas_Cobrar!L13)
A16: =IF(Ctas_Cobrar!A14="","",Ctas_Cobrar!A14) | B16: =IF(Ctas_Cobrar!B14="","",Ctas_Cobrar!B14) | C16: =IF(Ctas_Cobrar!C14="","",Ctas_Cobrar!C14) | D16: =IF(Ctas_Cobrar!D14="","",Ctas_Cobrar!D14) | E16: =IF(Ctas_Cobrar!E14="","",Ctas_Cobrar!E14) | F16: =IF(Ctas_Cobrar!F14="","",Ctas_Cobrar!F14) | G16: =IF(Ctas_Cobrar!G14="","",Ctas_Cobrar!G14) | H16: =IF(Ctas_Cobrar!H14="","",Ctas_Cobrar!H14) | I16: =IF(Ctas_Cobrar!I14="","",Ctas_Cobrar!I14) | J16: =IF(Ctas_Cobrar!L14="","",Ctas_Cobrar!L14)
A17: =IF(Ctas_Cobrar!A15="","",Ctas_Cobrar!A15) | B17: =IF(Ctas_Cobrar!B15="","",Ctas_Cobrar!B15) | C17: =IF(Ctas_Cobrar!C15="","",Ctas_Cobrar!C15) | D17: =IF(Ctas_Cobrar!D15="","",Ctas_Cobrar!D15) | E17: =IF(Ctas_Cobrar!E15="","",Ctas_Cobrar!E15) | F17: =IF(Ctas_Cobrar!F15="","",Ctas_Cobrar!F15) | G17: =IF(Ctas_Cobrar!G15="","",Ctas_Cobrar!G15) | H17: =IF(Ctas_Cobrar!H15="","",Ctas_Cobrar!H15) | I17: =IF(Ctas_Cobrar!I15="","",Ctas_Cobrar!I15) | J17: =IF(Ctas_Cobrar!L15="","",Ctas_Cobrar!L15)
A18: =IF(Ctas_Cobrar!A16="","",Ctas_Cobrar!A16) | B18: =IF(Ctas_Cobrar!B16="","",Ctas_Cobrar!B16) | C18: =IF(Ctas_Cobrar!C16="","",Ctas_Cobrar!C16) | D18: =IF(Ctas_Cobrar!D16="","",Ctas_Cobrar!D16) | E18: =IF(Ctas_Cobrar!E16="","",Ctas_Cobrar!E16) | F18: =IF(Ctas_Cobrar!F16="","",Ctas_Cobrar!F16) | G18: =IF(Ctas_Cobrar!G16="","",Ctas_Cobrar!G16) | H18: =IF(Ctas_Cobrar!H16="","",Ctas_Cobrar!H16) | I18: =IF(Ctas_Cobrar!I16="","",Ctas_Cobrar!I16) | J18: =IF(Ctas_Cobrar!L16="","",Ctas_Cobrar!L16)
... A56: =IF(Ctas_Cobrar!A54="","",Ctas_Cobrar!A54) | B56: =IF(Ctas_Cobrar!B54="","",Ctas_Cobrar!B54) | C56: =IF(Ctas_Cobrar!C54="","",Ctas_Cobrar!C54) | D56: =IF(Ctas_Cobrar!D54="","",Ctas_Cobrar!D54) | E56: =IF(Ctas_Cobrar!E54="","",Ctas_Cobrar!E54) | F56: =IF(Ctas_Cobrar!F54="","",Ctas_Cobrar!F54) | G56: =IF(Ctas_Cobrar!G54="","",Ctas_Cobrar!G54) | H56: =IF(Ctas_Cobrar!H54="","",Ctas_Cobrar!H54) | I56: =IF(Ctas_Cobrar!I54="","",Ctas_Cobrar!I54) | J56: =IF(Ctas_Cobrar!L54="","",Ctas_Cobrar!L54)
A59: 📤 PAGOS PENDIENTES (desde Cuentas por Pagar)
A60: N° OC | B60: Fecha | C60: Proveedor | D60: Importe | E60: Pagado | F60: Saldo | G60: Vencimiento | H60: Estado | I60: Días Atraso | J60: Alerta
A61: =IF(Ctas_Pagar!A5="","",Ctas_Pagar!A5) | B61: =IF(Ctas_Pagar!B5="","",Ctas_Pagar!B5) | C61: =IF(Ctas_Pagar!C5="","",Ctas_Pagar!C5) | D61: =IF(Ctas_Pagar!D5="","",Ctas_Pagar!D5) | E61: =IF(Ctas_Pagar!E5="","",Ctas_Pagar!E5) | F61: =IF(Ctas_Pagar!F5="","",Ctas_Pagar!F5) | G61: =IF(Ctas_Pagar!G5="","",Ctas_Pagar!G5) | H61: =IF(Ctas_Pagar!H5="","",Ctas_Pagar!H5) | I61: =IF(Ctas_Pagar!I5="","",Ctas_Pagar!I5) | J61: =IF(Ctas_Pagar!K5="","",Ctas_Pagar!K5)
A62: =IF(Ctas_Pagar!A6="","",Ctas_Pagar!A6) | B62: =IF(Ctas_Pagar!B6="","",Ctas_Pagar!B6) | C62: =IF(Ctas_Pagar!C6="","",Ctas_Pagar!C6) | D62: =IF(Ctas_Pagar!D6="","",Ctas_Pagar!D6) | E62: =IF(Ctas_Pagar!E6="","",Ctas_Pagar!E6) | F62: =IF(Ctas_Pagar!F6="","",Ctas_Pagar!F6) | G62: =IF(Ctas_Pagar!G6="","",Ctas_Pagar!G6) | H62: =IF(Ctas_Pagar!H6="","",Ctas_Pagar!H6) | I62: =IF(Ctas_Pagar!I6="","",Ctas_Pagar!I6) | J62: =IF(Ctas_Pagar!K6="","",Ctas_Pagar!K6)
A63: =IF(Ctas_Pagar!A7="","",Ctas_Pagar!A7) | B63: =IF(Ctas_Pagar!B7="","",Ctas_Pagar!B7) | C63: =IF(Ctas_Pagar!C7="","",Ctas_Pagar!C7) | D63: =IF(Ctas_Pagar!D7="","",Ctas_Pagar!D7) | E63: =IF(Ctas_Pagar!E7="","",Ctas_Pagar!E7) | F63: =IF(Ctas_Pagar!F7="","",Ctas_Pagar!F7) | G63: =IF(Ctas_Pagar!G7="","",Ctas_Pagar!G7) | H63: =IF(Ctas_Pagar!H7="","",Ctas_Pagar!H7) | I63: =IF(Ctas_Pagar!I7="","",Ctas_Pagar!I7) | J63: =IF(Ctas_Pagar!K7="","",Ctas_Pagar!K7)
A64: =IF(Ctas_Pagar!A8="","",Ctas_Pagar!A8) | B64: =IF(Ctas_Pagar!B8="","",Ctas_Pagar!B8) | C64: =IF(Ctas_Pagar!C8="","",Ctas_Pagar!C8) | D64: =IF(Ctas_Pagar!D8="","",Ctas_Pagar!D8) | E64: =IF(Ctas_Pagar!E8="","",Ctas_Pagar!E8) | F64: =IF(Ctas_Pagar!F8="","",Ctas_Pagar!F8) | G64: =IF(Ctas_Pagar!G8="","",Ctas_Pagar!G8) | H64: =IF(Ctas_Pagar!H8="","",Ctas_Pagar!H8) | I64: =IF(Ctas_Pagar!I8="","",Ctas_Pagar!I8) | J64: =IF(Ctas_Pagar!K8="","",Ctas_Pagar!K8)
A65: =IF(Ctas_Pagar!A9="","",Ctas_Pagar!A9) | B65: =IF(Ctas_Pagar!B9="","",Ctas_Pagar!B9) | C65: =IF(Ctas_Pagar!C9="","",Ctas_Pagar!C9) | D65: =IF(Ctas_Pagar!D9="","",Ctas_Pagar!D9) | E65: =IF(Ctas_Pagar!E9="","",Ctas_Pagar!E9) | F65: =IF(Ctas_Pagar!F9="","",Ctas_Pagar!F9) | G65: =IF(Ctas_Pagar!G9="","",Ctas_Pagar!G9) | H65: =IF(Ctas_Pagar!H9="","",Ctas_Pagar!H9) | I65: =IF(Ctas_Pagar!I9="","",Ctas_Pagar!I9) | J65: =IF(Ctas_Pagar!K9="","",Ctas_Pagar!K9)
A66: =IF(Ctas_Pagar!A10="","",Ctas_Pagar!A10) | B66: =IF(Ctas_Pagar!B10="","",Ctas_Pagar!B10) | C66: =IF(Ctas_Pagar!C10="","",Ctas_Pagar!C10) | D66: =IF(Ctas_Pagar!D10="","",Ctas_Pagar!D10) | E66: =IF(Ctas_Pagar!E10="","",Ctas_Pagar!E10) | F66: =IF(Ctas_Pagar!F10="","",Ctas_Pagar!F10) | G66: =IF(Ctas_Pagar!G10="","",Ctas_Pagar!G10) | H66: =IF(Ctas_Pagar!H10="","",Ctas_Pagar!H10) | I66: =IF(Ctas_Pagar!I10="","",Ctas_Pagar!I10) | J66: =IF(Ctas_Pagar!K10="","",Ctas_Pagar!K10)
A67: =IF(Ctas_Pagar!A11="","",Ctas_Pagar!A11) | B67: =IF(Ctas_Pagar!B11="","",Ctas_Pagar!B11) | C67: =IF(Ctas_Pagar!C11="","",Ctas_Pagar!C11) | D67: =IF(Ctas_Pagar!D11="","",Ctas_Pagar!D11) | E67: =IF(Ctas_Pagar!E11="","",Ctas_Pagar!E11) | F67: =IF(Ctas_Pagar!F11="","",Ctas_Pagar!F11) | G67: =IF(Ctas_Pagar!G11="","",Ctas_Pagar!G11) | H67: =IF(Ctas_Pagar!H11="","",Ctas_Pagar!H11) | I67: =IF(Ctas_Pagar!I11="","",Ctas_Pagar!I11) | J67: =IF(Ctas_Pagar!K11="","",Ctas_Pagar!K11)
A68: =IF(Ctas_Pagar!A12="","",Ctas_Pagar!A12) | B68: =IF(Ctas_Pagar!B12="","",Ctas_Pagar!B12) | C68: =IF(Ctas_Pagar!C12="","",Ctas_Pagar!C12) | D68: =IF(Ctas_Pagar!D12="","",Ctas_Pagar!D12) | E68: =IF(Ctas_Pagar!E12="","",Ctas_Pagar!E12) | F68: =IF(Ctas_Pagar!F12="","",Ctas_Pagar!F12) | G68: =IF(Ctas_Pagar!G12="","",Ctas_Pagar!G12) | H68: =IF(Ctas_Pagar!H12="","",Ctas_Pagar!H12) | I68: =IF(Ctas_Pagar!I12="","",Ctas_Pagar!I12) | J68: =IF(Ctas_Pagar!K12="","",Ctas_Pagar!K12)
A69: =IF(Ctas_Pagar!A13="","",Ctas_Pagar!A13) | B69: =IF(Ctas_Pagar!B13="","",Ctas_Pagar!B13) | C69: =IF(Ctas_Pagar!C13="","",Ctas_Pagar!C13) | D69: =IF(Ctas_Pagar!D13="","",Ctas_Pagar!D13) | E69: =IF(Ctas_Pagar!E13="","",Ctas_Pagar!E13) | F69: =IF(Ctas_Pagar!F13="","",Ctas_Pagar!F13) | G69: =IF(Ctas_Pagar!G13="","",Ctas_Pagar!G13) | H69: =IF(Ctas_Pagar!H13="","",Ctas_Pagar!H13) | I69: =IF(Ctas_Pagar!I13="","",Ctas_Pagar!I13) | J69: =IF(Ctas_Pagar!K13="","",Ctas_Pagar!K13)
A70: =IF(Ctas_Pagar!A14="","",Ctas_Pagar!A14) | B70: =IF(Ctas_Pagar!B14="","",Ctas_Pagar!B14) | C70: =IF(Ctas_Pagar!C14="","",Ctas_Pagar!C14) | D70: =IF(Ctas_Pagar!D14="","",Ctas_Pagar!D14) | E70: =IF(Ctas_Pagar!E14="","",Ctas_Pagar!E14) | F70: =IF(Ctas_Pagar!F14="","",Ctas_Pagar!F14) | G70: =IF(Ctas_Pagar!G14="","",Ctas_Pagar!G14) | H70: =IF(Ctas_Pagar!H14="","",Ctas_Pagar!H14) | I70: =IF(Ctas_Pagar!I14="","",Ctas_Pagar!I14) | J70: =IF(Ctas_Pagar!K14="","",Ctas_Pagar!K14)
A71: =IF(Ctas_Pagar!A15="","",Ctas_Pagar!A15) | B71: =IF(Ctas_Pagar!B15="","",Ctas_Pagar!B15) | C71: =IF(Ctas_Pagar!C15="","",Ctas_Pagar!C15) | D71: =IF(Ctas_Pagar!D15="","",Ctas_Pagar!D15) | E71: =IF(Ctas_Pagar!E15="","",Ctas_Pagar!E15) | F71: =IF(Ctas_Pagar!F15="","",Ctas_Pagar!F15) | G71: =IF(Ctas_Pagar!G15="","",Ctas_Pagar!G15) | H71: =IF(Ctas_Pagar!H15="","",Ctas_Pagar!H15) | I71: =IF(Ctas_Pagar!I15="","",Ctas_Pagar!I15) | J71: =IF(Ctas_Pagar!K15="","",Ctas_Pagar!K15)
A72: =IF(Ctas_Pagar!A16="","",Ctas_Pagar!A16) | B72: =IF(Ctas_Pagar!B16="","",Ctas_Pagar!B16) | C72: =IF(Ctas_Pagar!C16="","",Ctas_Pagar!C16) | D72: =IF(Ctas_Pagar!D16="","",Ctas_Pagar!D16) | E72: =IF(Ctas_Pagar!E16="","",Ctas_Pagar!E16) | F72: =IF(Ctas_Pagar!F16="","",Ctas_Pagar!F16) | G72: =IF(Ctas_Pagar!G16="","",Ctas_Pagar!G16) | H72: =IF(Ctas_Pagar!H16="","",Ctas_Pagar!H16) | I72: =IF(Ctas_Pagar!I16="","",Ctas_Pagar!I16) | J72: =IF(Ctas_Pagar!K16="","",Ctas_Pagar!K16)
... A110: =IF(Ctas_Pagar!A54="","",Ctas_Pagar!A54) | B110: =IF(Ctas_Pagar!B54="","",Ctas_Pagar!B54) | C110: =IF(Ctas_Pagar!C54="","",Ctas_Pagar!C54) | D110: =IF(Ctas_Pagar!D54="","",Ctas_Pagar!D54) | E110: =IF(Ctas_Pagar!E54="","",Ctas_Pagar!E54) | F110: =IF(Ctas_Pagar!F54="","",Ctas_Pagar!F54) | G110: =IF(Ctas_Pagar!G54="","",Ctas_Pagar!G54) | H110: =IF(Ctas_Pagar!H54="","",Ctas_Pagar!H54) | I110: =IF(Ctas_Pagar!I54="","",Ctas_Pagar!I54) | J110: =IF(Ctas_Pagar!K54="","",Ctas_Pagar!K54)

Sheet Clientes
A1: Base de datos de clientes | O1: Plantilla Empresarial
A2: 👥 BASE DE CLIENTES | Q2: Módulo CRM
A4: ID CLIENTE | B4: NOMBRE | C4: TIPO CLIENTE | D4: ID FISCAL | E4: DIRECCIÓN | F4: CIUDAD | G4: PROVINCIA | H4: CÓDIGO POSTAL | I4: CORREO | J4: TELÉFONO
A5: C001 | B5: Cliente Demo SpA | C5: Empresa | D5: 76.123.456-7 | E5: Av. Central 123 | F5: Santiago | G5: RM | H5: 8320000 | I5: cliente1@demo.cl | J5: 987654321
A6: C002 | B6: Comercial Andes Ltda. | C6: Empresa | D6: 77.234.567-8 | E6: Los Pinos 456 | F6: Valparaíso | G6: Valparaíso | H6: 2340000 | I6: cliente2@demo.cl | J6: 912345678

Sheet Proveedores
A1: Base de datos de proveedores | O1: Plantilla Empresarial
A2: 🏭 BASE DE PROVEEDORES | Q2: Módulo Compras
A4: ID PROV. | B4: NOMBRE | C4: ID FISCAL | D4: DIRECCIÓN | E4: CIUDAD | F4: PROVINCIA | G4: CORREO | H4: TELÉFONO | I4: PLAZO PAGO | J4: MEDIO PAGO
A5: P001 | B5: Distribuidora Norte | C5: 96.111.222-3 | D5: Ruta 5 100 | E5: Santiago | F5: RM | G5: proveedor1@demo.cl | H5: 998887766 | I5: 30 días | J5: Transferencia
A6: P002 | B6: Insumos del Sur | C6: 96.444.555-6 | D6: Camino Sur 88 | E6: Temuco | F6: La Araucanía | G6: proveedor2@demo.cl | H6: 977665544 | I6: 15 días | J6: Transferencia

Sheet Productos
A1: Maestro de productos, precios y stock mínimo | O1: Plantilla Empresarial
A2: 📦 MAESTRO DE PRODUCTOS | Q2: Módulo Inventario
A4: CÓDIGO | B4: CATEGORÍA | C4: PRODUCTO | D4: UNIDAD | E4: PRECIO VENTA | F4: PRECIO COMPRA | G4: STOCK MÍNIMO | H4: IVA % | I4: ACTIVO
A5: PR001 | B5: Bebidas | C5: Bebida Energética | D5: und | E5: 2500 | F5: 1800 | G5: 10 | H5: 0.19 | I5: Sí
A6: PR002 | B6: Bebidas | C6: Agua Mineral | D6: und | E6: 1200 | F6: 800 | G6: 15 | H6: 0.19 | I6: Sí
A7: PR003 | B7: Snacks | C7: Barra Proteica | D7: und | E7: 1800 | F7: 1200 | G7: 8 | H7: 0.19 | I7: Sí
A8: PR004 | B8: Abarrotes | C8: Café Molido | D8: und | E8: 6500 | F8: 4700 | G8: 5 | H8: 0.19 | I8: Sí

Sheet Ventas
A1: Registro de ventas | O1: Plantilla Empresarial
A2: 📋 REGISTRO DE VENTAS | Q2: Módulo Comercial
M3: =SUMIFS(H8:H89,J8:J89,MONTH(TODAY()),K8:K89,YEAR(TODAY())) | O3: Ventas del mes | Q3: =SUM(H8:H89)
A4: Registro comercial | O4: RESUMEN DEL MES
O5: Ventas del mes | Q5: =SUMIFS(H8:H89,J8:J89,MONTH(TODAY()),K8:K89,YEAR(TODAY()))
O6: N° documentos | Q6: =COUNTIF(A8:A89,"<>")
A7: N° DOC | B7: FECHA | C7: CLIENTE | D7: CÓDIGO | E7: PRODUCTO | F7: CANTIDAD | G7: P. UNIT | H7: TOTAL | I7: ESTADO COBRO | J7: MES | K7: AÑO | L7: OBS. | M7: UTILIDAD | O7: Ticket promedio | Q7: =IFERROR(SUMIFS(H8:H89,J8:J89,MONTH(TODAY()),K8:K89,YEAR(TODAY()))/COUNTIFS(J8:J89,MONTH(TODAY()),K8:K89,YEAR(TODAY())),0)
A8: 1 | B8: 46113 | C8: Cliente Demo SpA | D8: PR001 | E8: =IFERROR(VLOOKUP(D8,Productos!$A$5:$I$59,3,FALSE),"") | F8: 15 | G8: =IFERROR(VLOOKUP(D8,Productos!$A$5:$I$59,5,FALSE),0) | H8: =IFERROR(F8*G8,0) | I8: Cobrado | J8: =IF(B8="","",MONTH(B8)) | K8: =IF(B8="","",YEAR(B8)) | L8: Demo | M8: =IFERROR(H8-(F8*VLOOKUP(D8,Productos!$A$5:$I$59,6,FALSE)),0) | O8: Pendiente cobro | Q8: =SUMIFS(H8:H89,I8:I89,"Pendiente")
A9: 2 | B9: 46115 | C9: Comercial Andes Ltda. | D9: PR002 | E9: =IFERROR(VLOOKUP(D9,Productos!$A$5:$I$59,3,FALSE),"") | F9: 30 | G9: =IFERROR(VLOOKUP(D9,Productos!$A$5:$I$59,5,FALSE),0) | H9: =IFERROR(F9*G9,0) | I9: Cobrado | J9: =IF(B9="","",MONTH(B9)) | K9: =IF(B9="","",YEAR(B9)) | L9: Demo | M9: =IFERROR(H9-(F9*VLOOKUP(D9,Productos!$A$5:$I$59,6,FALSE)),0)
A10: 3 | B10: 46117 | C10: Cliente Demo SpA | D10: PR003 | E10: =IFERROR(VLOOKUP(D10,Productos!$A$5:$I$59,3,FALSE),"") | F10: 8 | G10: =IFERROR(VLOOKUP(D10,Productos!$A$5:$I$59,5,FALSE),0) | H10: =IFERROR(F10*G10,0) | I10: Cobrado | J10: =IF(B10="","",MONTH(B10)) | K10: =IF(B10="","",YEAR(B10)) | L10: Demo | M10: =IFERROR(H10-(F10*VLOOKUP(D10,Productos!$A$5:$I$59,6,FALSE)),0)
A11: 4 | B11: 46120 | C11: Comercial Andes Ltda. | D11: PR004 | E11: =IFERROR(VLOOKUP(D11,Productos!$A$5:$I$59,3,FALSE),"") | F11: 4 | G11: =IFERROR(VLOOKUP(D11,Productos!$A$5:$I$59,5,FALSE),0) | H11: =IFERROR(F11*G11,0) | I11: Pendiente | J11: =IF(B11="","",MONTH(B11)) | K11: =IF(B11="","",YEAR(B11)) | L11: Demo | M11: =IFERROR(H11-(F11*VLOOKUP(D11,Productos!$A$5:$I$59,6,FALSE)),0)
A12: 5 | B12: 46122 | C12: Cliente Demo SpA | D12: PR001 | E12: =IFERROR(VLOOKUP(D12,Productos!$A$5:$I$59,3,FALSE),"") | F12: 20 | G12: =IFERROR(VLOOKUP(D12,Productos!$A$5:$I$59,5,FALSE),0) | H12: =IFERROR(F12*G12,0) | I12: Cobrado | J12: =IF(B12="","",MONTH(B12)) | K12: =IF(B12="","",YEAR(B12)) | L12: Demo | M12: =IFERROR(H12-(F12*VLOOKUP(D12,Productos!$A$5:$I$59,6,FALSE)),0)
A13: 6 | B13: 46124 | C13: Comercial Andes Ltda. | D13: PR002 | E13: =IFERROR(VLOOKUP(D13,Productos!$A$5:$I$59,3,FALSE),"") | F13: 12 | G13: =IFERROR(VLOOKUP(D13,Productos!$A$5:$I$59,5,FALSE),0) | H13: =IFERROR(F13*G13,0) | I13: Pendiente | J13: =IF(B13="","",MONTH(B13)) | K13: =IF(B13="","",YEAR(B13)) | L13: Demo | M13: =IFERROR(H13-(F13*VLOOKUP(D13,Productos!$A$5:$I$59,6,FALSE)),0) | O13: Pendiente de cobro | Q13: =SUMIFS(H8:H89,I8:I89,"Pendiente")+SUMIFS(H8:H89,I8:I89,"Parcial")
A14: 7 | B14: 46126 | C14: Cliente Demo SpA | D14: PR003 | E14: =IFERROR(VLOOKUP(D14,Productos!$A$5:$I$59,3,FALSE),"") | F14: 6 | G14: =IFERROR(VLOOKUP(D14,Productos!$A$5:$I$59,5,FALSE),0) | H14: =IFERROR(F14*G14,0) | I14: Cobrado | J14: =IF(B14="","",MONTH(B14)) | K14: =IF(B14="","",YEAR(B14)) | L14: Demo | M14: =IFERROR(H14-(F14*VLOOKUP(D14,Productos!$A$5:$I$59,6,FALSE)),0)
A15: 8 | B15: 46128 | C15: Comercial Andes Ltda. | D15: PR001 | E15: =IFERROR(VLOOKUP(D15,Productos!$A$5:$I$59,3,FALSE),"") | F15: 10 | G15: =IFERROR(VLOOKUP(D15,Productos!$A$5:$I$59,5,FALSE),0) | H15: =IFERROR(F15*G15,0) | I15: Pendiente | J15: =IF(B15="","",MONTH(B15)) | K15: =IF(B15="","",YEAR(B15)) | L15: Demo | M15: =IFERROR(H15-(F15*VLOOKUP(D15,Productos!$A$5:$I$59,6,FALSE)),0)
E16: =IFERROR(VLOOKUP(D16,Productos!$A$5:$I$59,3,FALSE),"") | G16: =IFERROR(VLOOKUP(D16,Productos!$A$5:$I$59,5,FALSE),0) | H16: =IFERROR(F16*G16,0) | J16: =IF(B16="","",MONTH(B16)) | K16: =IF(B16="","",YEAR(B16)) | M16: =IFERROR(H16-(F16*VLOOKUP(D16,Productos!$A$5:$I$59,6,FALSE)),0)
E17: =IFERROR(VLOOKUP(D17,Productos!$A$5:$I$59,3,FALSE),"") | G17: =IFERROR(VLOOKUP(D17,Productos!$A$5:$I$59,5,FALSE),0) | H17: =IFERROR(F17*G17,0) | J17: =IF(B17="","",MONTH(B17)) | K17: =IF(B17="","",YEAR(B17)) | M17: =IFERROR(H17-(F17*VLOOKUP(D17,Productos!$A$5:$I$59,6,FALSE)),0)
E18: =IFERROR(VLOOKUP(D18,Productos!$A$5:$I$59,3,FALSE),"") | G18: =IFERROR(VLOOKUP(D18,Productos!$A$5:$I$59,5,FALSE),0) | H18: =IFERROR(F18*G18,0) | J18: =IF(B18="","",MONTH(B18)) | K18: =IF(B18="","",YEAR(B18)) | M18: =IFERROR(H18-(F18*VLOOKUP(D18,Productos!$A$5:$I$59,6,FALSE)),0)
E19: =IFERROR(VLOOKUP(D19,Productos!$A$5:$I$59,3,FALSE),"") | G19: =IFERROR(VLOOKUP(D19,Productos!$A$5:$I$59,5,FALSE),0) | H19: =IFERROR(F19*G19,0) | J19: =IF(B19="","",MONTH(B19)) | K19: =IF(B19="","",YEAR(B19)) | M19: =IFERROR(H19-(F19*VLOOKUP(D19,Productos!$A$5:$I$59,6,FALSE)),0)
E20: =IFERROR(VLOOKUP(D20,Productos!$A$5:$I$59,3,FALSE),"") | G20: =IFERROR(VLOOKUP(D20,Productos!$A$5:$I$59,5,FALSE),0) | H20: =IFERROR(F20*G20,0) | J20: =IF(B20="","",MONTH(B20)) | K20: =IF(B20="","",YEAR(B20)) | M20: =IFERROR(H20-(F20*VLOOKUP(D20,Productos!$A$5:$I$59,6,FALSE)),0)
E21: =IFERROR(VLOOKUP(D21,Productos!$A$5:$I$59,3,FALSE),"") | G21: =IFERROR(VLOOKUP(D21,Productos!$A$5:$I$59,5,FALSE),0) | H21: =IFERROR(F21*G21,0) | J21: =IF(B21="","",MONTH(B21)) | K21: =IF(B21="","",YEAR(B21)) | M21: =IFERROR(H21-(F21*VLOOKUP(D21,Productos!$A$5:$I$59,6,FALSE)),0)
E22: =IFERROR(VLOOKUP(D22,Productos!$A$5:$I$59,3,FALSE),"") | G22: =IFERROR(VLOOKUP(D22,Productos!$A$5:$I$59,5,FALSE),0) | H22: =IFERROR(F22*G22,0) | J22: =IF(B22="","",MONTH(B22)) | K22: =IF(B22="","",YEAR(B22)) | M22: =IFERROR(H22-(F22*VLOOKUP(D22,Productos!$A$5:$I$59,6,FALSE)),0)
E23: =IFERROR(VLOOKUP(D23,Productos!$A$5:$I$59,3,FALSE),"") | G23: =IFERROR(VLOOKUP(D23,Productos!$A$5:$I$59,5,FALSE),0) | H23: =IFERROR(F23*G23,0) | J23: =IF(B23="","",MONTH(B23)) | K23: =IF(B23="","",YEAR(B23)) | M23: =IFERROR(H23-(F23*VLOOKUP(D23,Productos!$A$5:$I$59,6,FALSE)),0)
E24: =IFERROR(VLOOKUP(D24,Productos!$A$5:$I$59,3,FALSE),"") | G24: =IFERROR(VLOOKUP(D24,Productos!$A$5:$I$59,5,FALSE),0) | H24: =IFERROR(F24*G24,0) | J24: =IF(B24="","",MONTH(B24)) | K24: =IF(B24="","",YEAR(B24)) | M24: =IFERROR(H24-(F24*VLOOKUP(D24,Productos!$A$5:$I$59,6,FALSE)),0)
E25: =IFERROR(VLOOKUP(D25,Productos!$A$5:$I$59,3,FALSE),"") | G25: =IFERROR(VLOOKUP(D25,Productos!$A$5:$I$59,5,FALSE),0) | H25: =IFERROR(F25*G25,0) | J25: =IF(B25="","",MONTH(B25)) | K25: =IF(B25="","",YEAR(B25)) | M25: =IFERROR(H25-(F25*VLOOKUP(D25,Productos!$A$5:$I$59,6,FALSE)),0)
E26: =IFERROR(VLOOKUP(D26,Productos!$A$5:$I$59,3,FALSE),"") | G26: =IFERROR(VLOOKUP(D26,Productos!$A$5:$I$59,5,FALSE),0) | H26: =IFERROR(F26*G26,0) | J26: =IF(B26="","",MONTH(B26)) | K26: =IF(B26="","",YEAR(B26)) | M26: =IFERROR(H26-(F26*VLOOKUP(D26,Productos!$A$5:$I$59,6,FALSE)),0)
E27: =IFERROR(VLOOKUP(D27,Productos!$A$5:$I$59,3,FALSE),"") | G27: =IFERROR(VLOOKUP(D27,Productos!$A$5:$I$59,5,FALSE),0) | H27: =IFERROR(F27*G27,0) | J27: =IF(B27="","",MONTH(B27)) | K27: =IF(B27="","",YEAR(B27)) | M27: =IFERROR(H27-(F27*VLOOKUP(D27,Productos!$A$5:$I$59,6,FALSE)),0)
... E89: =IFERROR(VLOOKUP(D89,Productos!$A$5:$I$59,3,FALSE),"") | G89: =IFERROR(VLOOKUP(D89,Productos!$A$5:$I$59,5,FALSE),0) | H89: =IFERROR(F89*G89,0) | J89: =IF(B89="","",MONTH(B89)) | K89: =IF(B89="","",YEAR(B89)) | M89: =IFERROR(H89-(F89*VLOOKUP(D89,Productos!$A$5:$I$59,6,FALSE)),0)

Sheet Doc_Venta
A1: Documento de venta | O1: Plantilla Empresarial
A2: 🧾 DOCUMENTO DE VENTA | Q2: Factura / Presupuesto
A4: [Mi Empresa] | D4: PRESUPUESTO / FACTURA | I4: FACTURAR | K4: REHACER | M4: IMPRIMIR
A5: [Domicilio]
A6: [ID Fiscal]
A8: CLIENTE | D8: N° DOCUMENTO | F8: 1 | I8: Control
D9: FECHA | F9: =TODAY()
D10: VENCIMIENTO | F10: =F9+30 | I10: Stock actual | J10: A vender | K10: Stock mínimo | L10: Advertencia
I11: =IFERROR(VLOOKUP(A15,Inventario!$A$8:$N$58,7,FALSE),0) | J11: =IF(A15="","",C15) | K11: =IFERROR(VLOOKUP(A15,Productos!$A$5:$I$59,7,FALSE),0) | L11: =IF(A15="","",IF(J11<=MAX(I11-K11,0),"Stock suficiente","Revisar stock"))
I12: =IFERROR(VLOOKUP(A16,Inventario!$A$8:$N$58,7,FALSE),0) | J12: =IF(A16="","",C16) | K12: =IFERROR(VLOOKUP(A16,Productos!$A$5:$I$59,7,FALSE),0) | L12: =IF(A16="","",IF(J12<=MAX(I12-K12,0),"Stock suficiente","Revisar stock"))
I13: =IFERROR(VLOOKUP(A17,Inventario!$A$8:$N$58,7,FALSE),0) | J13: =IF(A17="","",C17) | K13: =IFERROR(VLOOKUP(A17,Productos!$A$5:$I$59,7,FALSE),0) | L13: =IF(A17="","",IF(J13<=MAX(I13-K13,0),"Stock suficiente","Revisar stock"))
A14: CÓDIGO | B14: ARTÍCULO | C14: CANTIDAD | D14: PRECIO UNIT. | E14: TOTAL | I14: =IFERROR(VLOOKUP(A18,Inventario!$A$8:$N$58,7,FALSE),0) | J14: =IF(A18="","",C18) | K14: =IFERROR(VLOOKUP(A18,Productos!$A$5:$I$59,7,FALSE),0) | L14: =IF(A18="","",IF(J14<=MAX(I14-K14,0),"Stock suficiente","Revisar stock"))
B15: =IFERROR(VLOOKUP(A15,Productos!$A$5:$I$59,3,FALSE),"") | D15: =IFERROR(VLOOKUP(A15,Productos!$A$5:$I$59,5,FALSE),0) | E15: =IFERROR(C15*D15,0) | I15: =IFERROR(VLOOKUP(A19,Inventario!$A$8:$N$58,7,FALSE),0) | J15: =IF(A19="","",C19) | K15: =IFERROR(VLOOKUP(A19,Productos!$A$5:$I$59,7,FALSE),0) | L15: =IF(A19="","",IF(J15<=MAX(I15-K15,0),"Stock suficiente","Revisar stock"))
B16: =IFERROR(VLOOKUP(A16,Productos!$A$5:$I$59,3,FALSE),"") | D16: =IFERROR(VLOOKUP(A16,Productos!$A$5:$I$59,5,FALSE),0) | E16: =IFERROR(C16*D16,0) | I16: =IFERROR(VLOOKUP(A20,Inventario!$A$8:$N$58,7,FALSE),0) | J16: =IF(A20="","",C20) | K16: =IFERROR(VLOOKUP(A20,Productos!$A$5:$I$59,7,FALSE),0) | L16: =IF(A20="","",IF(J16<=MAX(I16-K16,0),"Stock suficiente","Revisar stock"))
B17: =IFERROR(VLOOKUP(A17,Productos!$A$5:$I$59,3,FALSE),"") | D17: =IFERROR(VLOOKUP(A17,Productos!$A$5:$I$59,5,FALSE),0) | E17: =IFERROR(C17*D17,0)
B18: =IFERROR(VLOOKUP(A18,Productos!$A$5:$I$59,3,FALSE),"") | D18: =IFERROR(VLOOKUP(A18,Productos!$A$5:$I$59,5,FALSE),0) | E18: =IFERROR(C18*D18,0)
B19: =IFERROR(VLOOKUP(A19,Productos!$A$5:$I$59,3,FALSE),"") | D19: =IFERROR(VLOOKUP(A19,Productos!$A$5:$I$59,5,FALSE),0) | E19: =IFERROR(C19*D19,0)
B20: =IFERROR(VLOOKUP(A20,Productos!$A$5:$I$59,3,FALSE),"") | D20: =IFERROR(VLOOKUP(A20,Productos!$A$5:$I$59,5,FALSE),0) | E20: =IFERROR(C20*D20,0)
B21: =IFERROR(VLOOKUP(A21,Productos!$A$5:$I$59,3,FALSE),"") | D21: =IFERROR(VLOOKUP(A21,Productos!$A$5:$I$59,5,FALSE),0) | E21: =IFERROR(C21*D21,0)
B22: =IFERROR(VLOOKUP(A22,Productos!$A$5:$I$59,3,FALSE),"") | D22: =IFERROR(VLOOKUP(A22,Productos!$A$5:$I$59,5,FALSE),0) | E22: =IFERROR(C22*D22,0)
B23: =IFERROR(VLOOKUP(A23,Productos!$A$5:$I$59,3,FALSE),"") | D23: =IFERROR(VLOOKUP(A23,Productos!$A$5:$I$59,5,FALSE),0) | E23: =IFERROR(C23*D23,0)
B24: =IFERROR(VLOOKUP(A24,Productos!$A$5:$I$59,3,FALSE),"") | D24: =IFERROR(VLOOKUP(A24,Productos!$A$5:$I$59,5,FALSE),0) | E24: =IFERROR(C24*D24,0)
B25: =IFERROR(VLOOKUP(A25,Productos!$A$5:$I$59,3,FALSE),"") | D25: =IFERROR(VLOOKUP(A25,Productos!$A$5:$I$59,5,FALSE),0) | E25: =IFERROR(C25*D25,0)
B26: =IFERROR(VLOOKUP(A26,Productos!$A$5:$I$59,3,FALSE),"") | D26: =IFERROR(VLOOKUP(A26,Productos!$A$5:$I$59,5,FALSE),0) | E26: =IFERROR(C26*D26,0)
D29: SUBTOTAL | E29: =SUM(E15:E26)
D30: IVA | E30: =E29*0.19
D31: TOTAL | E31: =E29+E30

Sheet Compras
A1: Registro de compras | O1: Plantilla Empresarial
A2: 🛒 REGISTRO DE COMPRAS | Q2: Módulo Proveedores
L3: =SUMIFS(H8:H89,I8:I89,MONTH(TODAY()),J8:J89,YEAR(TODAY()))
A4: Registro de compras | N4: RESUMEN DEL MES
N5: Compras del mes | P5: =SUMIFS(H8:H89,I8:I89,MONTH(TODAY()),J8:J89,YEAR(TODAY()))
N6: N° órdenes | P6: =COUNTIF(A8:A89,"<>")
A7: N° OC | B7: FECHA | C7: PROVEEDOR | D7: CÓDIGO | E7: PRODUCTO | F7: CANTIDAD | G7: COSTO UNIT | H7: TOTAL | I7: MES | J7: AÑO | K7: ESTADO PAGO | L7: OBS. | N7: Promedio OC | P7: =IFERROR(SUMIFS(H8:H89,I8:I89,MONTH(TODAY()),J8:J89,YEAR(TODAY()))/COUNTIFS(I8:I89,MONTH(TODAY()),J8:J89,YEAR(TODAY())),0)
A8: 1 | B8: 46114 | C8: Distribuidora Norte | D8: PR001 | E8: =IFERROR(VLOOKUP(D8,Productos!$A$5:$I$59,3,FALSE),"") | F8: 50 | G8: =IFERROR(VLOOKUP(D8,Productos!$A$5:$I$59,6,FALSE),0) | H8: =IFERROR(F8*G8,0) | I8: =IF(B8="","",MONTH(B8)) | J8: =IF(B8="","",YEAR(B8)) | K8: Pagado | L8: Demo | N8: Pendiente pago | P8: =SUMIFS(H8:H89,K8:K89,"Pendiente")
A9: 2 | B9: 46116 | C9: Insumos del Sur | D9: PR002 | E9: =IFERROR(VLOOKUP(D9,Productos!$A$5:$I$59,3,FALSE),"") | F9: 80 | G9: =IFERROR(VLOOKUP(D9,Productos!$A$5:$I$59,6,FALSE),0) | H9: =IFERROR(F9*G9,0) | I9: =IF(B9="","",MONTH(B9)) | J9: =IF(B9="","",YEAR(B9)) | K9: Pagado | L9: Demo
A10: 3 | B10: 46119 | C10: Distribuidora Norte | D10: PR003 | E10: =IFERROR(VLOOKUP(D10,Productos!$A$5:$I$59,3,FALSE),"") | F10: 30 | G10: =IFERROR(VLOOKUP(D10,Productos!$A$5:$I$59,6,FALSE),0) | H10: =IFERROR(F10*G10,0) | I10: =IF(B10="","",MONTH(B10)) | J10: =IF(B10="","",YEAR(B10)) | K10: Pagado | L10: Demo
A11: 4 | B11: 46121 | C11: Insumos del Sur | D11: PR004 | E11: =IFERROR(VLOOKUP(D11,Productos!$A$5:$I$59,3,FALSE),"") | F11: 10 | G11: =IFERROR(VLOOKUP(D11,Productos!$A$5:$I$59,6,FALSE),0) | H11: =IFERROR(F11*G11,0) | I11: =IF(B11="","",MONTH(B11)) | J11: =IF(B11="","",YEAR(B11)) | K11: Pendiente | L11: Demo
A12: 5 | B12: 46125 | C12: Distribuidora Norte | D12: PR001 | E12: =IFERROR(VLOOKUP(D12,Productos!$A$5:$I$59,3,FALSE),"") | F12: 40 | G12: =IFERROR(VLOOKUP(D12,Productos!$A$5:$I$59,6,FALSE),0) | H12: =IFERROR(F12*G12,0) | I12: =IF(B12="","",MONTH(B12)) | J12: =IF(B12="","",YEAR(B12)) | K12: Pendiente | L12: Demo
E13: =IFERROR(VLOOKUP(D13,Productos!$A$5:$I$59,3,FALSE),"") | G13: =IFERROR(VLOOKUP(D13,Productos!$A$5:$I$59,6,FALSE),0) | H13: =IFERROR(F13*G13,0) | I13: =IF(B13="","",MONTH(B13)) | J13: =IF(B13="","",YEAR(B13))
E14: =IFERROR(VLOOKUP(D14,Productos!$A$5:$I$59,3,FALSE),"") | G14: =IFERROR(VLOOKUP(D14,Productos!$A$5:$I$59,6,FALSE),0) | H14: =IFERROR(F14*G14,0) | I14: =IF(B14="","",MONTH(B14)) | J14: =IF(B14="","",YEAR(B14))
E15: =IFERROR(VLOOKUP(D15,Productos!$A$5:$I$59,3,FALSE),"") | G15: =IFERROR(VLOOKUP(D15,Productos!$A$5:$I$59,6,FALSE),0) | H15: =IFERROR(F15*G15,0) | I15: =IF(B15="","",MONTH(B15)) | J15: =IF(B15="","",YEAR(B15))
E16: =IFERROR(VLOOKUP(D16,Productos!$A$5:$I$59,3,FALSE),"") | G16: =IFERROR(VLOOKUP(D16,Productos!$A$5:$I$59,6,FALSE),0) | H16: =IFERROR(F16*G16,0) | I16: =IF(B16="","",MONTH(B16)) | J16: =IF(B16="","",YEAR(B16))
E17: =IFERROR(VLOOKUP(D17,Productos!$A$5:$I$59,3,FALSE),"") | G17: =IFERROR(VLOOKUP(D17,Productos!$A$5:$I$59,6,FALSE),0) | H17: =IFERROR(F17*G17,0) | I17: =IF(B17="","",MONTH(B17)) | J17: =IF(B17="","",YEAR(B17))
E18: =IFERROR(VLOOKUP(D18,Productos!$A$5:$I$59,3,FALSE),"") | G18: =IFERROR(VLOOKUP(D18,Productos!$A$5:$I$59,6,FALSE),0) | H18: =IFERROR(F18*G18,0) | I18: =IF(B18="","",MONTH(B18)) | J18: =IF(B18="","",YEAR(B18))
E19: =IFERROR(VLOOKUP(D19,Productos!$A$5:$I$59,3,FALSE),"") | G19: =IFERROR(VLOOKUP(D19,Productos!$A$5:$I$59,6,FALSE),0) | H19: =IFERROR(F19*G19,0) | I19: =IF(B19="","",MONTH(B19)) | J19: =IF(B19="","",YEAR(B19))
E20: =IFERROR(VLOOKUP(D20,Productos!$A$5:$I$59,3,FALSE),"") | G20: =IFERROR(VLOOKUP(D20,Productos!$A$5:$I$59,6,FALSE),0) | H20: =IFERROR(F20*G20,0) | I20: =IF(B20="","",MONTH(B20)) | J20: =IF(B20="","",YEAR(B20))
E21: =IFERROR(VLOOKUP(D21,Productos!$A$5:$I$59,3,FALSE),"") | G21: =IFERROR(VLOOKUP(D21,Productos!$A$5:$I$59,6,FALSE),0) | H21: =IFERROR(F21*G21,0) | I21: =IF(B21="","",MONTH(B21)) | J21: =IF(B21="","",YEAR(B21))
E22: =IFERROR(VLOOKUP(D22,Productos!$A$5:$I$59,3,FALSE),"") | G22: =IFERROR(VLOOKUP(D22,Productos!$A$5:$I$59,6,FALSE),0) | H22: =IFERROR(F22*G22,0) | I22: =IF(B22="","",MONTH(B22)) | J22: =IF(B22="","",YEAR(B22))
E23: =IFERROR(VLOOKUP(D23,Productos!$A$5:$I$59,3,FALSE),"") | G23: =IFERROR(VLOOKUP(D23,Productos!$A$5:$I$59,6,FALSE),0) | H23: =IFERROR(F23*G23,0) | I23: =IF(B23="","",MONTH(B23)) | J23: =IF(B23="","",YEAR(B23))
E24: =IFERROR(VLOOKUP(D24,Productos!$A$5:$I$59,3,FALSE),"") | G24: =IFERROR(VLOOKUP(D24,Productos!$A$5:$I$59,6,FALSE),0) | H24: =IFERROR(F24*G24,0) | I24: =IF(B24="","",MONTH(B24)) | J24: =IF(B24="","",YEAR(B24))
... E89: =IFERROR(VLOOKUP(D89,Productos!$A$5:$I$59,3,FALSE),"") | G89: =IFERROR(VLOOKUP(D89,Productos!$A$5:$I$59,6,FALSE),0) | H89: =IFERROR(F89*G89,0) | I89: =IF(B89="","",MONTH(B89)) | J89: =IF(B89="","",YEAR(B89))

Sheet Orden_Compra
A1: Orden de compra | O1: Plantilla Empresarial
A2: 📋 ORDEN DE COMPRA | Q2: Módulo Proveedores
A4: [Mi Empresa] | D4: N° ORDEN | F4: 1
A5: [Domicilio] | D5: FECHA | F5: =TODAY()
A6: [ID Fiscal]
A8: ENVIAR A:
A10: PROVEEDOR | D10: ENTREGA
A11: DOMICILIO | D11: PLAZO
A12: CIUDAD | D12: PAGO
A13: CONTACTO
A14: TELÉFONO
A17: N° | B17: ARTÍCULO | C17: CANTIDAD | D17: PRECIO UNITARIO | E17: PRECIO TOTAL
A18: 1 | E18: =IFERROR(C18*D18,0)
A19: 2 | E19: =IFERROR(C19*D19,0)
A20: 3 | E20: =IFERROR(C20*D20,0)
A21: 4 | E21: =IFERROR(C21*D21,0)
A22: 5 | E22: =IFERROR(C22*D22,0)
A23: 6 | E23: =IFERROR(C23*D23,0)
A24: 7 | E24: =IFERROR(C24*D24,0)
A25: 8 | E25: =IFERROR(C25*D25,0)
A26: 9 | E26: =IFERROR(C26*D26,0)
A27: 10 | E27: =IFERROR(C27*D27,0)
A28: 11 | E28: =IFERROR(C28*D28,0)
A29: 12 | E29: =IFERROR(C29*D29,0)
D31: SUB-TOTAL | E31: =SUM(E18:E29)
D32: IVA | E32: =E31*0.19
D33: TOTAL | E33: =E31+E32

Sheet Inventario
A1: Gestión de inventario | O1: Plantilla Empresarial
A2: 🗄️ CONTROL DE INVENTARIO | Q2: Módulo Stock
M3: =SUM(L8:L58) | N3: =COUNTIF(N8:N58,1)
A4: Control de stock
A7: CÓDIGO | B7: PRODUCTO | C7: UNIDAD | D7: STOCK INICIAL | E7: ENTRADAS | F7: SALIDAS | G7: STOCK ACTUAL | H7: STOCK MÍNIMO | I7: ALERTA | J7: PRECIO COMPRA | K7: PRECIO VENTA | L7: VALOR COSTO | M7: VALOR VENTA | N7: BAJO MÍNIMO
A8: PR001 | E8: =IF(A8="","",SUMIFS(Compras!$F:$F,Compras!$D:$D,A8)) | F8: =IF(A8="","",SUMIFS(Ventas!$F:$F,Ventas!$D:$D,A8)) | G8: =IF(A8="","",D8+E8-F8) | H8: =IFERROR(VLOOKUP(A8,Productos!$A$5:$I$59,7,FALSE),0) | I8: =IF(A8="","",IF(G8<=H8,"Reponer","Suficiente")) | J8: =IFERROR(VLOOKUP(A8,Productos!$A$5:$I$59,6,FALSE),0) | K8: =IFERROR(VLOOKUP(A8,Productos!$A$5:$I$59,5,FALSE),0) | L8: =IF(A8="","",G8*J8) | M8: =IF(A8="","",G8*K8) | N8: =IF(A8="","",IF(G8<=H8,1,0)) | P8: Reponer | Q8: =COUNTIF(I8:I58,"Reponer")
A9: PR002 | E9: =IF(A9="","",SUMIFS(Compras!$F:$F,Compras!$D:$D,A9)) | F9: =IF(A9="","",SUMIFS(Ventas!$F:$F,Ventas!$D:$D,A9)) | G9: =IF(A9="","",D9+E9-F9) | H9: =IFERROR(VLOOKUP(A9,Productos!$A$5:$I$59,7,FALSE),0) | I9: =IF(A9="","",IF(G9<=H9,"Reponer","Suficiente")) | J9: =IFERROR(VLOOKUP(A9,Productos!$A$5:$I$59,6,FALSE),0) | K9: =IFERROR(VLOOKUP(A9,Productos!$A$5:$I$59,5,FALSE),0) | L9: =IF(A9="","",G9*J9) | M9: =IF(A9="","",G9*K9) | N9: =IF(A9="","",IF(G9<=H9,1,0)) | P9: Suficiente | Q9: =COUNTIF(I8:I58,"Suficiente")
A10: PR003 | E10: =IF(A10="","",SUMIFS(Compras!$F:$F,Compras!$D:$D,A10)) | F10: =IF(A10="","",SUMIFS(Ventas!$F:$F,Ventas!$D:$D,A10)) | G10: =IF(A10="","",D10+E10-F10) | H10: =IFERROR(VLOOKUP(A10,Productos!$A$5:$I$59,7,FALSE),0) | I10: =IF(A10="","",IF(G10<=H10,"Reponer","Suficiente")) | J10: =IFERROR(VLOOKUP(A10,Productos!$A$5:$I$59,6,FALSE),0) | K10: =IFERROR(VLOOKUP(A10,Productos!$A$5:$I$59,5,FALSE),0) | L10: =IF(A10="","",G10*J10) | M10: =IF(A10="","",G10*K10) | N10: =IF(A10="","",IF(G10<=H10,1,0))
A11: PR004 | E11: =IF(A11="","",SUMIFS(Compras!$F:$F,Compras!$D:$D,A11)) | F11: =IF(A11="","",SUMIFS(Ventas!$F:$F,Ventas!$D:$D,A11)) | G11: =IF(A11="","",D11+E11-F11) | H11: =IFERROR(VLOOKUP(A11,Productos!$A$5:$I$59,7,FALSE),0) | I11: =IF(A11="","",IF(G11<=H11,"Reponer","Suficiente")) | J11: =IFERROR(VLOOKUP(A11,Productos!$A$5:$I$59,6,FALSE),0) | K11: =IFERROR(VLOOKUP(A11,Productos!$A$5:$I$59,5,FALSE),0) | L11: =IF(A11="","",G11*J11) | M11: =IF(A11="","",G11*K11) | N11: =IF(A11="","",IF(G11<=H11,1,0))
E12: =IF(A12="","",SUMIFS(Compras!$F:$F,Compras!$D:$D,A12)) | F12: =IF(A12="","",SUMIFS(Ventas!$F:$F,Ventas!$D:$D,A12)) | G12: =IF(A12="","",D12+E12-F12) | H12: =IFERROR(VLOOKUP(A12,Productos!$A$5:$I$59,7,FALSE),0) | I12: =IF(A12="","",IF(G12<=H12,"Reponer","Suficiente")) | J12: =IFERROR(VLOOKUP(A12,Productos!$A$5:$I$59,6,FALSE),0) | K12: =IFERROR(VLOOKUP(A12,Productos!$A$5:$I$59,5,FALSE),0) | L12: =IF(A12="","",G12*J12) | M12: =IF(A12="","",G12*K12) | N12: =IF(A12="","",IF(G12<=H12,1,0))
E13: =IF(A13="","",SUMIFS(Compras!$F:$F,Compras!$D:$D,A13)) | F13: =IF(A13="","",SUMIFS(Ventas!$F:$F,Ventas!$D:$D,A13)) | G13: =IF(A13="","",D13+E13-F13) | H13: =IFERROR(VLOOKUP(A13,Productos!$A$5:$I$59,7,FALSE),0) | I13: =IF(A13="","",IF(G13<=H13,"Reponer","Suficiente")) | J13: =IFERROR(VLOOKUP(A13,Productos!$A$5:$I$59,6,FALSE),0) | K13: =IFERROR(VLOOKUP(A13,Productos!$A$5:$I$59,5,FALSE),0) | L13: =IF(A13="","",G13*J13) | M13: =IF(A13="","",G13*K13) | N13: =IF(A13="","",IF(G13<=H13,1,0))
E14: =IF(A14="","",SUMIFS(Compras!$F:$F,Compras!$D:$D,A14)) | F14: =IF(A14="","",SUMIFS(Ventas!$F:$F,Ventas!$D:$D,A14)) | G14: =IF(A14="","",D14+E14-F14) | H14: =IFERROR(VLOOKUP(A14,Productos!$A$5:$I$59,7,FALSE),0) | I14: =IF(A14="","",IF(G14<=H14,"Reponer","Suficiente")) | J14: =IFERROR(VLOOKUP(A14,Productos!$A$5:$I$59,6,FALSE),0) | K14: =IFERROR(VLOOKUP(A14,Productos!$A$5:$I$59,5,FALSE),0) | L14: =IF(A14="","",G14*J14) | M14: =IF(A14="","",G14*K14) | N14: =IF(A14="","",IF(G14<=H14,1,0))
E15: =IF(A15="","",SUMIFS(Compras!$F:$F,Compras!$D:$D,A15)) | F15: =IF(A15="","",SUMIFS(Ventas!$F:$F,Ventas!$D:$D,A15)) | G15: =IF(A15="","",D15+E15-F15) | H15: =IFERROR(VLOOKUP(A15,Productos!$A$5:$I$59,7,FALSE),0) | I15: =IF(A15="","",IF(G15<=H15,"Reponer","Suficiente")) | J15: =IFERROR(VLOOKUP(A15,Productos!$A$5:$I$59,6,FALSE),0) | K15: =IFERROR(VLOOKUP(A15,Productos!$A$5:$I$59,5,FALSE),0) | L15: =IF(A15="","",G15*J15) | M15: =IF(A15="","",G15*K15) | N15: =IF(A15="","",IF(G15<=H15,1,0))
E16: =IF(A16="","",SUMIFS(Compras!$F:$F,Compras!$D:$D,A16)) | F16: =IF(A16="","",SUMIFS(Ventas!$F:$F,Ventas!$D:$D,A16)) | G16: =IF(A16="","",D16+E16-F16) | H16: =IFERROR(VLOOKUP(A16,Productos!$A$5:$I$59,7,FALSE),0) | I16: =IF(A16="","",IF(G16<=H16,"Reponer","Suficiente")) | J16: =IFERROR(VLOOKUP(A16,Productos!$A$5:$I$59,6,FALSE),0) | K16: =IFERROR(VLOOKUP(A16,Productos!$A$5:$I$59,5,FALSE),0) | L16: =IF(A16="","",G16*J16) | M16: =IF(A16="","",G16*K16) | N16: =IF(A16="","",IF(G16<=H16,1,0))
E17: =IF(A17="","",SUMIFS(Compras!$F:$F,Compras!$D:$D,A17)) | F17: =IF(A17="","",SUMIFS(Ventas!$F:$F,Ventas!$D:$D,A17)) | G17: =IF(A17="","",D17+E17-F17) | H17: =IFERROR(VLOOKUP(A17,Productos!$A$5:$I$59,7,FALSE),0) | I17: =IF(A17="","",IF(G17<=H17,"Reponer","Suficiente")) | J17: =IFERROR(VLOOKUP(A17,Productos!$A$5:$I$59,6,FALSE),0) | K17: =IFERROR(VLOOKUP(A17,Productos!$A$5:$I$59,5,FALSE),0) | L17: =IF(A17="","",G17*J17) | M17: =IF(A17="","",G17*K17) | N17: =IF(A17="","",IF(G17<=H17,1,0))
E18: =IF(A18="","",SUMIFS(Compras!$F:$F,Compras!$D:$D,A18)) | F18: =IF(A18="","",SUMIFS(Ventas!$F:$F,Ventas!$D:$D,A18)) | G18: =IF(A18="","",D18+E18-F18) | H18: =IFERROR(VLOOKUP(A18,Productos!$A$5:$I$59,7,FALSE),0) | I18: =IF(A18="","",IF(G18<=H18,"Reponer","Suficiente")) | J18: =IFERROR(VLOOKUP(A18,Productos!$A$5:$I$59,6,FALSE),0) | K18: =IFERROR(VLOOKUP(A18,Productos!$A$5:$I$59,5,FALSE),0) | L18: =IF(A18="","",G18*J18) | M18: =IF(A18="","",G18*K18) | N18: =IF(A18="","",IF(G18<=H18,1,0))
E19: =IF(A19="","",SUMIFS(Compras!$F:$F,Compras!$D:$D,A19)) | F19: =IF(A19="","",SUMIFS(Ventas!$F:$F,Ventas!$D:$D,A19)) | G19: =IF(A19="","",D19+E19-F19) | H19: =IFERROR(VLOOKUP(A19,Productos!$A$5:$I$59,7,FALSE),0) | I19: =IF(A19="","",IF(G19<=H19,"Reponer","Suficiente")) | J19: =IFERROR(VLOOKUP(A19,Productos!$A$5:$I$59,6,FALSE),0) | K19: =IFERROR(VLOOKUP(A19,Productos!$A$5:$I$59,5,FALSE),0) | L19: =IF(A19="","",G19*J19) | M19: =IF(A19="","",G19*K19) | N19: =IF(A19="","",IF(G19<=H19,1,0))
E20: =IF(A20="","",SUMIFS(Compras!$F:$F,Compras!$D:$D,A20)) | F20: =IF(A20="","",SUMIFS(Ventas!$F:$F,Ventas!$D:$D,A20)) | G20: =IF(A20="","",D20+E20-F20) | H20: =IFERROR(VLOOKUP(A20,Productos!$A$5:$I$59,7,FALSE),0) | I20: =IF(A20="","",IF(G20<=H20,"Reponer","Suficiente")) | J20: =IFERROR(VLOOKUP(A20,Productos!$A$5:$I$59,6,FALSE),0) | K20: =IFERROR(VLOOKUP(A20,Productos!$A$5:$I$59,5,FALSE),0) | L20: =IF(A20="","",G20*J20) | M20: =IF(A20="","",G20*K20) | N20: =IF(A20="","",IF(G20<=H20,1,0))
E21: =IF(A21="","",SUMIFS(Compras!$F:$F,Compras!$D:$D,A21)) | F21: =IF(A21="","",SUMIFS(Ventas!$F:$F,Ventas!$D:$D,A21)) | G21: =IF(A21="","",D21+E21-F21) | H21: =IFERROR(VLOOKUP(A21,Productos!$A$5:$I$59,7,FALSE),0) | I21: =IF(A21="","",IF(G21<=H21,"Reponer","Suficiente")) | J21: =IFERROR(VLOOKUP(A21,Productos!$A$5:$I$59,6,FALSE),0) | K21: =IFERROR(VLOOKUP(A21,Productos!$A$5:$I$59,5,FALSE),0) | L21: =IF(A21="","",G21*J21) | M21: =IF(A21="","",G21*K21) | N21: =IF(A21="","",IF(G21<=H21,1,0))
E22: =IF(A22="","",SUMIFS(Compras!$F:$F,Compras!$D:$D,A22)) | F22: =IF(A22="","",SUMIFS(Ventas!$F:$F,Ventas!$D:$D,A22)) | G22: =IF(A22="","",D22+E22-F22) | H22: =IFERROR(VLOOKUP(A22,Productos!$A$5:$I$59,7,FALSE),0) | I22: =IF(A22="","",IF(G22<=H22,"Reponer","Suficiente")) | J22: =IFERROR(VLOOKUP(A22,Productos!$A$5:$I$59,6,FALSE),0) | K22: =IFERROR(VLOOKUP(A22,Productos!$A$5:$I$59,5,FALSE),0) | L22: =IF(A22="","",G22*J22) | M22: =IF(A22="","",G22*K22) | N22: =IF(A22="","",IF(G22<=H22,1,0))
E23: =IF(A23="","",SUMIFS(Compras!$F:$F,Compras!$D:$D,A23)) | F23: =IF(A23="","",SUMIFS(Ventas!$F:$F,Ventas!$D:$D,A23)) | G23: =IF(A23="","",D23+E23-F23) | H23: =IFERROR(VLOOKUP(A23,Productos!$A$5:$I$59,7,FALSE),0) | I23: =IF(A23="","",IF(G23<=H23,"Reponer","Suficiente")) | J23: =IFERROR(VLOOKUP(A23,Productos!$A$5:$I$59,6,FALSE),0) | K23: =IFERROR(VLOOKUP(A23,Productos!$A$5:$I$59,5,FALSE),0) | L23: =IF(A23="","",G23*J23) | M23: =IF(A23="","",G23*K23) | N23: =IF(A23="","",IF(G23<=H23,1,0))
... E58: =IF(A58="","",SUMIFS(Compras!$F:$F,Compras!$D:$D,A58)) | F58: =IF(A58="","",SUMIFS(Ventas!$F:$F,Ventas!$D:$D,A58)) | G58: =IF(A58="","",D58+E58-F58) | H58: =IFERROR(VLOOKUP(A58,Productos!$A$5:$I$59,7,FALSE),0) | I58: =IF(A58="","",IF(G58<=H58,"Reponer","Suficiente")) | J58: =IFERROR(VLOOKUP(A58,Productos!$A$5:$I$59,6,FALSE),0) | K58: =IFERROR(VLOOKUP(A58,Productos!$A$5:$I$59,5,FALSE),0) | L58: =IF(A58="","",G58*J58) | M58: =IF(A58="","",G58*K58) | N58: =IF(A58="","",IF(G58<=H58,1,0))

Sheet Caja
A1: Control de caja | O1: Plantilla Empresarial
A2: 💵 CONTROL DE CAJA | Q2: Módulo Tesorería
A4: Lista los tipos de caja | D4: Ingresa los saldos a mantener en caja | J4: Resumen de caja
Q6: =O7
A7: Nro. | B7: Tipo de Caja | D7: Mínimo | E7: 500 | J7: SALDO TOTAL DE CAJA | O7: =SUM(K11:K15)
A8: 001 | B8: Efectivo | D8: Máximo | E8: 4500
A9: 002 | B9: Banco
A10: 003 | B10: Mercado Pago | J10: TIPO DE CAJA | K10: SALDO
A11: 004 | B11: PayPal | J11: =IF(B8="","","Saldo en "&B8) | K11: =SUMIF($C$18:$C$89,A8,$D$18:$D$89)-SUMIF($C$18:$C$89,A8,$E$18:$E$89)
A12: 005 | B12: Otros | J12: =IF(B9="","","Saldo en "&B9) | K12: =SUMIF($C$18:$C$89,A9,$D$18:$D$89)-SUMIF($C$18:$C$89,A9,$E$18:$E$89)
J13: =IF(B10="","","Saldo en "&B10) | K13: =SUMIF($C$18:$C$89,A10,$D$18:$D$89)-SUMIF($C$18:$C$89,A10,$E$18:$E$89)
A14: Ingresa los movimientos de caja diarios | J14: =IF(B11="","","Saldo en "&B11) | K14: =SUMIF($C$18:$C$89,A11,$D$18:$D$89)-SUMIF($C$18:$C$89,A11,$E$18:$E$89)
J15: =IF(B12="","","Saldo en "&B12) | K15: =SUMIF($C$18:$C$89,A12,$D$18:$D$89)-SUMIF($C$18:$C$89,A12,$E$18:$E$89)
A17: FECHA | B17: CONCEPTO | C17: CÓDIGO | D17: ENTRADAS | E17: SALIDAS | F17: SALDO | G17: OBS.
A18: 46113 | B18: Saldo inicial | C18: Ingreso | D18: 500000 | F18: =IF(C18="","",D18-E18) | J18: Advertencia
A19: 46114 | B19: Cobro factura C001 | C19: Ingreso | D19: 37500 | F19: =IF(C19="","",F18+D19-E19) | J19: =IF(E8="","",IF(O7>E8,"Se superó el máximo a mantener en caja en un monto equivalente a $"&TEXT(O7-E8,"#,##0.00"),IF(O7<E7,"La caja es inferior a su mínimo tolerable en un monto equivalente a $"&TEXT(E7-O7,"#,##0.00"),"Caja dentro de rango")))
A20: 46115 | B20: Pago proveedor Dist. Norte | C20: Egreso | E20: 90000 | F20: =IF(C20="","",F19+D20-E20)
A21: 46117 | B21: Cobro factura C002 | C21: Ingreso | D21: 75000 | F21: =IF(C21="","",F20+D21-E21)
A22: 46119 | B22: Pago arriendo local | C22: Egreso | E22: 350000 | F22: =IF(C22="","",F21+D22-E22)
A23: 46120 | B23: Cobro contado | C23: Ingreso | D23: 50000 | F23: =IF(C23="","",F22+D23-E23)
A24: 46122 | B24: Servicios básicos | C24: Egreso | E24: 45000 | F24: =IF(C24="","",F23+D24-E24)
A25: 46124 | B25: Cobro factura C001 | C25: Ingreso | D25: 25000 | F25: =IF(C25="","",F24+D25-E25)
A26: 46126 | B26: Compra insumos | C26: Egreso | E26: 22400 | F26: =IF(C26="","",F25+D26-E26)
A27: 46127 | B27: Venta contado | C27: Ingreso | D27: 18000 | F27: =IF(C27="","",F26+D27-E27)
F28: =IF(C28="","",F27+D28-E28)
F29: =IF(C29="","",F28+D29-E29)
F30: =IF(C30="","",F29+D30-E30)
F31: =IF(C31="","",F30+D31-E31)
F32: =IF(C32="","",F31+D32-E32)
F33: =IF(C33="","",F32+D33-E33)
F34: =IF(C34="","",F33+D34-E34)
F35: =IF(C35="","",F34+D35-E35)
F36: =IF(C36="","",F35+D36-E36)
F37: =IF(C37="","",F36+D37-E37)
F38: =IF(C38="","",F37+D38-E38)
F39: =IF(C39="","",F38+D39-E39)
... F89: =IF(C89="","",F88+D89-E89)

Sheet Ctas_Cobrar
A1: Cuentas por cobrar | O1: Plantilla Empresarial
A2: 📥 CUENTAS POR COBRAR | Q2: Control Cartera
L3: =SUMIFS(F:F,H:H,"Pendiente")+SUMIFS(F:F,H:H,"Vencido")
A4: N° DOC | B4: FECHA | C4: CLIENTE | D4: IMPORTE VENTA | E4: IMPORTE COBRADO | F4: SALDO PENDIENTE | G4: FECHA VENC. | H4: ESTADO | I4: DÍAS ATRASO | J4: MES | K4: OBS. | L4: ALERTA
A5: =Ventas!A8 | B5: =Ventas!B8 | C5: =Ventas!C8 | D5: =Ventas!H8 | E5: 0 | F5: =IF(A5="","",D5-E5) | G5: =IF(B5="","",B5+30) | H5: =IF(A5="","",IF(F5=0,"Cobrado",IF(TODAY()>G5,"Vencido","Pendiente"))) | I5: =IF(H5="Vencido",TODAY()-G5,0) | J5: =IF(B5="","",MONTH(B5)) | L5: =IF(H5="Vencido","Cobro urgente",IF(H5="Pendiente","Seguimiento","OK"))
A6: =Ventas!A9 | B6: =Ventas!B9 | C6: =Ventas!C9 | D6: =Ventas!H9 | E6: 0 | F6: =IF(A6="","",D6-E6) | G6: =IF(B6="","",B6+30) | H6: =IF(A6="","",IF(F6=0,"Cobrado",IF(TODAY()>G6,"Vencido","Pendiente"))) | I6: =IF(H6="Vencido",TODAY()-G6,0) | J6: =IF(B6="","",MONTH(B6)) | L6: =IF(H6="Vencido","Cobro urgente",IF(H6="Pendiente","Seguimiento","OK"))
A7: =Ventas!A10 | B7: =Ventas!B10 | C7: =Ventas!C10 | D7: =Ventas!H10 | E7: 0 | F7: =IF(A7="","",D7-E7) | G7: =IF(B7="","",B7+30) | H7: =IF(A7="","",IF(F7=0,"Cobrado",IF(TODAY()>G7,"Vencido","Pendiente"))) | I7: =IF(H7="Vencido",TODAY()-G7,0) | J7: =IF(B7="","",MONTH(B7)) | L7: =IF(H7="Vencido","Cobro urgente",IF(H7="Pendiente","Seguimiento","OK"))
A8: =Ventas!A11 | B8: =Ventas!B11 | C8: =Ventas!C11 | D8: =Ventas!H11 | E8: 0 | F8: =IF(A8="","",D8-E8) | G8: =IF(B8="","",B8+30) | H8: =IF(A8="","",IF(F8=0,"Cobrado",IF(TODAY()>G8,"Vencido","Pendiente"))) | I8: =IF(H8="Vencido",TODAY()-G8,0) | J8: =IF(B8="","",MONTH(B8)) | L8: =IF(H8="Vencido","Cobro urgente",IF(H8="Pendiente","Seguimiento","OK"))
A9: =Ventas!A12 | B9: =Ventas!B12 | C9: =Ventas!C12 | D9: =Ventas!H12 | E9: 0 | F9: =IF(A9="","",D9-E9) | G9: =IF(B9="","",B9+30) | H9: =IF(A9="","",IF(F9=0,"Cobrado",IF(TODAY()>G9,"Vencido","Pendiente"))) | I9: =IF(H9="Vencido",TODAY()-G9,0) | J9: =IF(B9="","",MONTH(B9)) | L9: =IF(H9="Vencido","Cobro urgente",IF(H9="Pendiente","Seguimiento","OK"))
A10: =Ventas!A13 | B10: =Ventas!B13 | C10: =Ventas!C13 | D10: =Ventas!H13 | E10: 0 | F10: =IF(A10="","",D10-E10) | G10: =IF(B10="","",B10+30) | H10: =IF(A10="","",IF(F10=0,"Cobrado",IF(TODAY()>G10,"Vencido","Pendiente"))) | I10: =IF(H10="Vencido",TODAY()-G10,0) | J10: =IF(B10="","",MONTH(B10)) | L10: =IF(H10="Vencido","Cobro urgente",IF(H10="Pendiente","Seguimiento","OK"))
A11: =Ventas!A14 | B11: =Ventas!B14 | C11: =Ventas!C14 | D11: =Ventas!H14 | E11: 0 | F11: =IF(A11="","",D11-E11) | G11: =IF(B11="","",B11+30) | H11: =IF(A11="","",IF(F11=0,"Cobrado",IF(TODAY()>G11,"Vencido","Pendiente"))) | I11: =IF(H11="Vencido",TODAY()-G11,0) | J11: =IF(B11="","",MONTH(B11)) | L11: =IF(H11="Vencido","Cobro urgente",IF(H11="Pendiente","Seguimiento","OK"))
A12: =Ventas!A15 | B12: =Ventas!B15 | C12: =Ventas!C15 | D12: =Ventas!H15 | E12: 0 | F12: =IF(A12="","",D12-E12) | G12: =IF(B12="","",B12+30) | H12: =IF(A12="","",IF(F12=0,"Cobrado",IF(TODAY()>G12,"Vencido","Pendiente"))) | I12: =IF(H12="Vencido",TODAY()-G12,0) | J12: =IF(B12="","",MONTH(B12)) | L12: =IF(H12="Vencido","Cobro urgente",IF(H12="Pendiente","Seguimiento","OK"))
A13: =Ventas!A16 | B13: =Ventas!B16 | C13: =Ventas!C16 | D13: =Ventas!H16 | E13: 0 | F13: =IF(A13="","",D13-E13) | G13: =IF(B13="","",B13+30) | H13: =IF(A13="","",IF(F13=0,"Cobrado",IF(TODAY()>G13,"Vencido","Pendiente"))) | I13: =IF(H13="Vencido",TODAY()-G13,0) | J13: =IF(B13="","",MONTH(B13)) | L13: =IF(H13="Vencido","Cobro urgente",IF(H13="Pendiente","Seguimiento","OK"))
A14: =Ventas!A17 | B14: =Ventas!B17 | C14: =Ventas!C17 | D14: =Ventas!H17 | E14: 0 | F14: =IF(A14="","",D14-E14) | G14: =IF(B14="","",B14+30) | H14: =IF(A14="","",IF(F14=0,"Cobrado",IF(TODAY()>G14,"Vencido","Pendiente"))) | I14: =IF(H14="Vencido",TODAY()-G14,0) | J14: =IF(B14="","",MONTH(B14)) | L14: =IF(H14="Vencido","Cobro urgente",IF(H14="Pendiente","Seguimiento","OK"))
A15: =Ventas!A18 | B15: =Ventas!B18 | C15: =Ventas!C18 | D15: =Ventas!H18 | E15: 0 | F15: =IF(A15="","",D15-E15) | G15: =IF(B15="","",B15+30) | H15: =IF(A15="","",IF(F15=0,"Cobrado",IF(TODAY()>G15,"Vencido","Pendiente"))) | I15: =IF(H15="Vencido",TODAY()-G15,0) | J15: =IF(B15="","",MONTH(B15)) | L15: =IF(H15="Vencido","Cobro urgente",IF(H15="Pendiente","Seguimiento","OK"))
A16: =Ventas!A19 | B16: =Ventas!B19 | C16: =Ventas!C19 | D16: =Ventas!H19 | E16: 0 | F16: =IF(A16="","",D16-E16) | G16: =IF(B16="","",B16+30) | H16: =IF(A16="","",IF(F16=0,"Cobrado",IF(TODAY()>G16,"Vencido","Pendiente"))) | I16: =IF(H16="Vencido",TODAY()-G16,0) | J16: =IF(B16="","",MONTH(B16)) | L16: =IF(H16="Vencido","Cobro urgente",IF(H16="Pendiente","Seguimiento","OK"))
